Workbook

Sheet title
A1: オフセット | B1: 名称 | C1: ウィンドウNo. | D1: 幅[px] | E1: 高さ[px] | F1: type | G1: type_idx | H1: st No.
A2: 0 | B2: 軸1 タイトル | C2: 1000 | D2: 800 | E2: 32 | F2: axis | G2: 1 | H2: {=IF(AND(LEN(F2)*LEN(G2)),IFERROR(INDEX(info_index!$D$2:$D$51,MATCH(F2&G2,info_index!$B$2:$B$51&info_index!$C$2:$C$51,0),1),""),"")} -> 7 | I2: *
A3: 1 | B3: 軸2 タイトル | C3: 1005 | D3: 800 | E3: 32 | F3: axis | G3: 2 | H3: {=IF(AND(LEN(F3)*LEN(G3)),IFERROR(INDEX(info_index!$D$2:$D$51,MATCH(F3&G3,info_index!$B$2:$B$51&info_index!$C$2:$C$51,0),1),""),"")} -> 6 | I3: *
A4: 2 | B4: 軸3 タイトル | C4: 1010 | D4: 800 | E4: 32 | F4: axis | G4: 3 | H4: {=IF(AND(LEN(F4)*LEN(G4)),IFERROR(INDEX(info_index!$D$2:$D$51,MATCH(F4&G4,info_index!$B$2:$B$51&info_index!$C$2:$C$51,0),1),""),"")} -> 7 | I4: *
A5: 3 | B5: 軸4 タイトル | C5: 1015 | D5: 800 | E5: 32 | F5: axis | G5: 4 | H5: {=IF(AND(LEN(F5)*LEN(G5)),IFERROR(INDEX(info_index!$D$2:$D$51,MATCH(F5&G5,info_index!$B$2:$B$51&info_index!$C$2:$C$51,0),1),""),"")} -> 8 | I5: *
A6: 4 | B6: 軸5 タイトル | C6: 1020 | D6: 800 | E6: 32 | F6: axis | G6: 5 | H6: {=IF(AND(LEN(F6)*LEN(G6)),IFERROR(INDEX(info_index!$D$2:$D$51,MATCH(F6&G6,info_index!$B$2:$B$51&info_index!$C$2:$C$51,0),1),""),"")} -> 3 | I6: *
A7: 5 | B7: 軸6 タイトル | C7: 1025 | D7: 800 | E7: 32 | F7: axis | G7: 6 | H7: {=IF(AND(LEN(F7)*LEN(G7)),IFERROR(INDEX(info_index!$D$2:$D$51,MATCH(F7&G7,info_index!$B$2:$B$51&info_index!$C$2:$C$51,0),1),""),"")} -> 3 | I7: *
A8: 6 | B8: 軸7 タイトル | C8: 1030 | D8: 800 | E8: 32 | F8: axis | G8: 7 | H8: {=IF(AND(LEN(F8)*LEN(G8)),IFERROR(INDEX(info_index!$D$2:$D$51,MATCH(F8&G8,info_index!$B$2:$B$51&info_index!$C$2:$C$51,0),1),""),"")} -> 1 | I8: *
A9: 7 | B9: 軸8 タイトル | C9: 1035 | D9: 800 | E9: 32 | F9: axis | G9: 8 | H9: {=IF(AND(LEN(F9)*LEN(G9)),IFERROR(INDEX(info_index!$D$2:$D$51,MATCH(F9&G9,info_index!$B$2:$B$51&info_index!$C$2:$C$51,0),1),""),"")} -> 10 | I9: *
A10: 8 | B10: 軸9 タイトル | C10: 1040 | D10: 800 | E10: 32 | F10: axis | G10: 9 | H10: {=IF(AND(LEN(F10)*LEN(G10)),IFERROR(INDEX(info_index!$D$2:$D$51,MATCH(F10&G10,info_index!$B$2:$B$51&info_index!$C$2:$C$51,0),1),""),"")} -> 10 | I10: *
A11: 9 | B11: 軸10 タイトル | C11: 1045 | D11: 800 | E11: 32 | F11: axis | G11: 10 | H11: {=IF(AND(LEN(F11)*LEN(G11)),IFERROR(INDEX(info_index!$D$2:$D$51,MATCH(F11&G11,info_index!$B$2:$B$51&info_index!$C$2:$C$51,0),1),""),"")} -> 0 | I11: *
A12: 10 | B12: 軸11 タイトル | C12: 1050 | D12: 800 | E12: 32 | F12: axis | G12: 11 | H12: {=IF(AND(LEN(F12)*LEN(G12)),IFERROR(INDEX(info_index!$D$2:$D$51,MATCH(F12&G12,info_index!$B$2:$B$51&info_index!$C$2:$C$51,0),1),""),"")} -> 0 | I12: *
A13: 11 | B13: 軸12 タイトル | C13: 1055 | D13: 800 | E13: 32 | F13: axis | G13: 12 | H13: {=IF(AND(LEN(F13)*LEN(G13)),IFERROR(INDEX(info_index!$D$2:$D$51,MATCH(F13&G13,info_index!$B$2:$B$51&info_index!$C$2:$C$51,0),1),""),"")} -> 0 | I13: *
... A37: 35 | B37: エレシリ1 タイトル | C37: 1200 | D37: 800 | E37: 32 | F37: EC | G37: 1 | H37: {=IF(AND(LEN(F37)*LEN(G37)),IFERROR(INDEX(info_index!$D$2:$D$51,MATCH(F37&G37,info_index!$B$2:$B$51&info_index!$C$2:$C$51,0),1),""),"")} -> 1 | I37: *
A38: 36 | H38: {=IF(AND(LEN(F38)*LEN(G38)),IFERROR(INDEX(info_index!$D$2:$D$51,MATCH(F38&G38,info_index!$B$2:$B$51&info_index!$C$2:$C$51,0),1),""),"")} | I38: *
A39: 37 | H39: {=IF(AND(LEN(F39)*LEN(G39)),IFERROR(INDEX(info_index!$D$2:$D$51,MATCH(F39&G39,info_index!$B$2:$B$51&info_index!$C$2:$C$51,0),1),""),"")} | I39: *
A40: 38 | H40: {=IF(AND(LEN(F40)*LEN(G40)),IFERROR(INDEX(info_index!$D$2:$D$51,MATCH(F40&G40,info_index!$B$2:$B$51&info_index!$C$2:$C$51,0),1),""),"")} | I40: *
A41: 39 | H41: {=IF(AND(LEN(F41)*LEN(G41)),IFERROR(INDEX(info_index!$D$2:$D$51,MATCH(F41&G41,info_index!$B$2:$B$51&info_index!$C$2:$C$51,0),1),""),"")} | I41: *
A42: 40 | H42: {=IF(AND(LEN(F42)*LEN(G42)),IFERROR(INDEX(info_index!$D$2:$D$51,MATCH(F42&G42,info_index!$B$2:$B$51&info_index!$C$2:$C$51,0),1),""),"")} | I42: *
A43: 41 | H43: {=IF(AND(LEN(F43)*LEN(G43)),IFERROR(INDEX(info_index!$D$2:$D$51,MATCH(F43&G43,info_index!$B$2:$B$51&info_index!$C$2:$C$51,0),1),""),"")} | I43: *
A44: 42 | H44: {=IF(AND(LEN(F44)*LEN(G44)),IFERROR(INDEX(info_index!$D$2:$D$51,MATCH(F44&G44,info_index!$B$2:$B$51&info_index!$C$2:$C$51,0),1),""),"")} | I44: *
A45: 43 | H45: {=IF(AND(LEN(F45)*LEN(G45)),IFERROR(INDEX(info_index!$D$2:$D$51,MATCH(F45&G45,info_index!$B$2:$B$51&info_index!$C$2:$C$51,0),1),""),"")} | I45: *
A46: 44 | H46: {=IF(AND(LEN(F46)*LEN(G46)),IFERROR(INDEX(info_index!$D$2:$D$51,MATCH(F46&G46,info_index!$B$2:$B$51&info_index!$C$2:$C$51,0),1),""),"")} | I46: *
A47: 45 | H47: {=IF(AND(LEN(F47)*LEN(G47)),IFERROR(INDEX(info_index!$D$2:$D$51,MATCH(F47&G47,info_index!$B$2:$B$51&info_index!$C$2:$C$51,0),1),""),"")} | I47: *
A48: 46 | H48: {=IF(AND(LEN(F48)*LEN(G48)),IFERROR(INDEX(info_index!$D$2:$D$51,MATCH(F48&G48,info_index!$B$2:$B$51&info_index!$C$2:$C$51,0),1),""),"")} | I48: *
A49: 47 | H49: {=IF(AND(LEN(F49)*LEN(G49)),IFERROR(INDEX(info_index!$D$2:$D$51,MATCH(F49&G49,info_index!$B$2:$B$51&info_index!$C$2:$C$51,0),1),""),"")} | I49: *
... A2049: 2047 | H2049: {=IF(AND(LEN(F2049)*LEN(G2049)),IFERROR(INDEX(info_index!$D$2:$D$51,MATCH(F2049&G2049,info_index!$B$2:$B$51&info_index!$C$2:$C$51,0),1),""),"")} | I2049: *

Sheet title_scripts
A1: 緒言 | D1: ウィンドウNo. | E1: id | F1: 名称 | G1: ウィンドウNo. | H1: 幅 | I1: 高さ | J1: ウィンドウあり | K1: ウィンドウ数 | L1: デバイス番号 | M1: =G1 -> ウィンドウNo. | O1: =H1 -> 幅 | P1: =I1 -> 高さ | Q1: スクリプト
A2: 開始デバイス | B2: 8260 | D2: 0 | E2: =IFERROR(INDEX(title!$A$2:$A$2049,MATCH($D2,title!$C$2:$C$2049,0),1),"") | F2: =IFERROR(INDEX(title!$B$2:$B$2049,MATCH($D2,title!$C$2:$C$2049,0),1),"") | G2: =IFERROR(INDEX(title!$C$2:$C$2049,MATCH($D2,title!$C$2:$C$2049,0),1),"") | H2: =IFERROR(INDEX(title!$D$2:$D$2049,MATCH($D2,title!$C$2:$C$2049,0),1),"") | I2: =IFERROR(INDEX(title!$E$2:$E$2049,MATCH($D2,title!$C$2:$C$2049,0),1),"") | J2: =IF(AND(LENB(G2),0<G2,LENB(H2),0<H2),"●","") | K2: =IF(LENB(J2),COUNTIF(J$2:J2,"●"),"") | L2: =IF(AND(LENB(K2),LENB($B$2),LENB($B$3)),$B$2+$B$3*(K2),"") | M2: =IF(LENB($L2),$B$4&$L2+COLUMN()-COLUMN($M2)&".U = "&G2&CHAR(9)&"'"&M$1,"") | O2: =IF(LENB($L2),$B$4&$L2+COLUMN()-COLUMN($M2)&".U = "&H2&CHAR(9)&"'"&O$1,"") | P2: =IF(LENB($L2),$B$4&$L2+COLUMN()-COLUMN($M2)&".U = "&I2&CHAR(9)&"'"&P$1,"") | Q2: =IF(LENB(K2),IF(1<K2,CHAR(10),"")&"'"&IF(F2=0,"名称未設定",F2)&CHAR(10)&M2&CHAR(10)&O2&CHAR(10)&P2,"")
A3: デバイス間隔 | B3: 4 | D3: 1 | E3: =IFERROR(INDEX(title!$A$2:$A$2049,MATCH($D3,title!$C$2:$C$2049,0),1),"") | F3: =IFERROR(INDEX(title!$B$2:$B$2049,MATCH($D3,title!$C$2:$C$2049,0),1),"") | G3: =IFERROR(INDEX(title!$C$2:$C$2049,MATCH($D3,title!$C$2:$C$2049,0),1),"") | H3: =IFERROR(INDEX(title!$D$2:$D$2049,MATCH($D3,title!$C$2:$C$2049,0),1),"") | I3: =IFERROR(INDEX(title!$E$2:$E$2049,MATCH($D3,title!$C$2:$C$2049,0),1),"") | J3: =IF(AND(LENB(G3),0<G3,LENB(H3),0<H3),"●","") | K3: =IF(LENB(J3),COUNTIF(J$2:J3,"●"),"") | L3: =IF(AND(LENB(K3),LENB($B$2),LENB($B$3)),$B$2+$B$3*(K3),"") | M3: =IF(LENB($L3),$B$4&$L3+COLUMN()-COLUMN($M3)&".U = "&G3&CHAR(9)&"'"&M$1,"") | O3: =IF(LENB($L3),$B$4&$L3+COLUMN()-COLUMN($M3)&".U = "&H3&CHAR(9)&"'"&O$1,"") | P3: =IF(LENB($L3),$B$4&$L3+COLUMN()-COLUMN($M3)&".U = "&I3&CHAR(9)&"'"&P$1,"") | Q3: =IF(LENB(K3),IF(1<K3,CHAR(10),"")&"'"&IF(F3=0,"名称未設定",F3)&CHAR(10)&M3&CHAR(10)&O3&CHAR(10)&P3,"")
A4: デバイス種別 | B4: DM | D4: 2 | E4: =IFERROR(INDEX(title!$A$2:$A$2049,MATCH($D4,title!$C$2:$C$2049,0),1),"") | F4: =IFERROR(INDEX(title!$B$2:$B$2049,MATCH($D4,title!$C$2:$C$2049,0),1),"") | G4: =IFERROR(INDEX(title!$C$2:$C$2049,MATCH($D4,title!$C$2:$C$2049,0),1),"") | H4: =IFERROR(INDEX(title!$D$2:$D$2049,MATCH($D4,title!$C$2:$C$2049,0),1),"") | I4: =IFERROR(INDEX(title!$E$2:$E$2049,MATCH($D4,title!$C$2:$C$2049,0),1),"") | J4: =IF(AND(LENB(G4),0<G4,LENB(H4),0<H4),"●","") | K4: =IF(LENB(J4),COUNTIF(J$2:J4,"●"),"") | L4: =IF(AND(LENB(K4),LENB($B$2),LENB($B$3)),$B$2+$B$3*(K4),"") | M4: =IF(LENB($L4),$B$4&$L4+COLUMN()-COLUMN($M4)&".U = "&G4&CHAR(9)&"'"&M$1,"") | O4: =IF(LENB($L4),$B$4&$L4+COLUMN()-COLUMN($M4)&".U = "&H4&CHAR(9)&"'"&O$1,"") | P4: =IF(LENB($L4),$B$4&$L4+COLUMN()-COLUMN($M4)&".U = "&I4&CHAR(9)&"'"&P$1,"") | Q4: =IF(LENB(K4),IF(1<K4,CHAR(10),"")&"'"&IF(F4=0,"名称未設定",F4)&CHAR(10)&M4&CHAR(10)&O4&CHAR(10)&P4,"")
D5: 3 | E5: =IFERROR(INDEX(title!$A$2:$A$2049,MATCH($D5,title!$C$2:$C$2049,0),1),"") | F5: =IFERROR(INDEX(title!$B$2:$B$2049,MATCH($D5,title!$C$2:$C$2049,0),1),"") | G5: =IFERROR(INDEX(title!$C$2:$C$2049,MATCH($D5,title!$C$2:$C$2049,0),1),"") | H5: =IFERROR(INDEX(title!$D$2:$D$2049,MATCH($D5,title!$C$2:$C$2049,0),1),"") | I5: =IFERROR(INDEX(title!$E$2:$E$2049,MATCH($D5,title!$C$2:$C$2049,0),1),"") | J5: =IF(AND(LENB(G5),0<G5,LENB(H5),0<H5),"●","") | K5: =IF(LENB(J5),COUNTIF(J$2:J5,"●"),"") | L5: =IF(AND(LENB(K5),LENB($B$2),LENB($B$3)),$B$2+$B$3*(K5),"") | M5: =IF(LENB($L5),$B$4&$L5+COLUMN()-COLUMN($M5)&".U = "&G5&CHAR(9)&"'"&M$1,"") | O5: =IF(LENB($L5),$B$4&$L5+COLUMN()-COLUMN($M5)&".U = "&H5&CHAR(9)&"'"&O$1,"") | P5: =IF(LENB($L5),$B$4&$L5+COLUMN()-COLUMN($M5)&".U = "&I5&CHAR(9)&"'"&P$1,"") | Q5: =IF(LENB(K5),IF(1<K5,CHAR(10),"")&"'"&IF(F5=0,"名称未設定",F5)&CHAR(10)&M5&CHAR(10)&O5&CHAR(10)&P5,"")
A6: 先頭注記 | B6: ="このスクリプトは "&B11&" によって生成されました。" -> このスクリプトは C:\tk\prj\hg-0025-0016\git\kv-x520\doc\[kv_script_conv_TP1_popup.xlsx]title_scripts(変数) によって生成されました。 | D6: 4 | E6: =IFERROR(INDEX(title!$A$2:$A$2049,MATCH($D6,title!$C$2:$C$2049,0),1),"") | F6: =IFERROR(INDEX(title!$B$2:$B$2049,MATCH($D6,title!$C$2:$C$2049,0),1),"") | G6: =IFERROR(INDEX(title!$C$2:$C$2049,MATCH($D6,title!$C$2:$C$2049,0),1),"") | H6: =IFERROR(INDEX(title!$D$2:$D$2049,MATCH($D6,title!$C$2:$C$2049,0),1),"") | I6: =IFERROR(INDEX(title!$E$2:$E$2049,MATCH($D6,title!$C$2:$C$2049,0),1),"") | J6: =IF(AND(LENB(G6),0<G6,LENB(H6),0<H6),"●","") | K6: =IF(LENB(J6),COUNTIF(J$2:J6,"●"),"") | L6: =IF(AND(LENB(K6),LENB($B$2),LENB($B$3)),$B$2+$B$3*(K6),"") | M6: =IF(LENB($L6),$B$4&$L6+COLUMN()-COLUMN($M6)&".U = "&G6&CHAR(9)&"'"&M$1,"") | O6: =IF(LENB($L6),$B$4&$L6+COLUMN()-COLUMN($M6)&".U = "&H6&CHAR(9)&"'"&O$1,"") | P6: =IF(LENB($L6),$B$4&$L6+COLUMN()-COLUMN($M6)&".U = "&I6&CHAR(9)&"'"&P$1,"") | Q6: =IF(LENB(K6),IF(1<K6,CHAR(10),"")&"'"&IF(F6=0,"名称未設定",F6)&CHAR(10)&M6&CHAR(10)&O6&CHAR(10)&P6,"")
A7: 末尾注記 | B7: -----ここまで生成script----- | D7: 5 | E7: =IFERROR(INDEX(title!$A$2:$A$2049,MATCH($D7,title!$C$2:$C$2049,0),1),"") | F7: =IFERROR(INDEX(title!$B$2:$B$2049,MATCH($D7,title!$C$2:$C$2049,0),1),"") | G7: =IFERROR(INDEX(title!$C$2:$C$2049,MATCH($D7,title!$C$2:$C$2049,0),1),"") | H7: =IFERROR(INDEX(title!$D$2:$D$2049,MATCH($D7,title!$C$2:$C$2049,0),1),"") | I7: =IFERROR(INDEX(title!$E$2:$E$2049,MATCH($D7,title!$C$2:$C$2049,0),1),"") | J7: =IF(AND(LENB(G7),0<G7,LENB(H7),0<H7),"●","") | K7: =IF(LENB(J7),COUNTIF(J$2:J7,"●"),"") | L7: =IF(AND(LENB(K7),LENB($B$2),LENB($B$3)),$B$2+$B$3*(K7),"") | M7: =IF(LENB($L7),$B$4&$L7+COLUMN()-COLUMN($M7)&".U = "&G7&CHAR(9)&"'"&M$1,"") | O7: =IF(LENB($L7),$B$4&$L7+COLUMN()-COLUMN($M7)&".U = "&H7&CHAR(9)&"'"&O$1,"") | P7: =IF(LENB($L7),$B$4&$L7+COLUMN()-COLUMN($M7)&".U = "&I7&CHAR(9)&"'"&P$1,"") | Q7: =IF(LENB(K7),IF(1<K7,CHAR(10),"")&"'"&IF(F7=0,"名称未設定",F7)&CHAR(10)&M7&CHAR(10)&O7&CHAR(10)&P7,"")
D8: 6 | E8: =IFERROR(INDEX(title!$A$2:$A$2049,MATCH($D8,title!$C$2:$C$2049,0),1),"") | F8: =IFERROR(INDEX(title!$B$2:$B$2049,MATCH($D8,title!$C$2:$C$2049,0),1),"") | G8: =IFERROR(INDEX(title!$C$2:$C$2049,MATCH($D8,title!$C$2:$C$2049,0),1),"") | H8: =IFERROR(INDEX(title!$D$2:$D$2049,MATCH($D8,title!$C$2:$C$2049,0),1),"") | I8: =IFERROR(INDEX(title!$E$2:$E$2049,MATCH($D8,title!$C$2:$C$2049,0),1),"") | J8: =IF(AND(LENB(G8),0<G8,LENB(H8),0<H8),"●","") | K8: =IF(LENB(J8),COUNTIF(J$2:J8,"●"),"") | L8: =IF(AND(LENB(K8),LENB($B$2),LENB($B$3)),$B$2+$B$3*(K8),"") | M8: =IF(LENB($L8),$B$4&$L8+COLUMN()-COLUMN($M8)&".U = "&G8&CHAR(9)&"'"&M$1,"") | O8: =IF(LENB($L8),$B$4&$L8+COLUMN()-COLUMN($M8)&".U = "&H8&CHAR(9)&"'"&O$1,"") | P8: =IF(LENB($L8),$B$4&$L8+COLUMN()-COLUMN($M8)&".U = "&I8&CHAR(9)&"'"&P$1,"") | Q8: =IF(LENB(K8),IF(1<K8,CHAR(10),"")&"'"&IF(F8=0,"名称未設定",F8)&CHAR(10)&M8&CHAR(10)&O8&CHAR(10)&P8,"")
D9: 7 | E9: =IFERROR(INDEX(title!$A$2:$A$2049,MATCH($D9,title!$C$2:$C$2049,0),1),"") | F9: =IFERROR(INDEX(title!$B$2:$B$2049,MATCH($D9,title!$C$2:$C$2049,0),1),"") | G9: =IFERROR(INDEX(title!$C$2:$C$2049,MATCH($D9,title!$C$2:$C$2049,0),1),"") | H9: =IFERROR(INDEX(title!$D$2:$D$2049,MATCH($D9,title!$C$2:$C$2049,0),1),"") | I9: =IFERROR(INDEX(title!$E$2:$E$2049,MATCH($D9,title!$C$2:$C$2049,0),1),"") | J9: =IF(AND(LENB(G9),0<G9,LENB(H9),0<H9),"●","") | K9: =IF(LENB(J9),COUNTIF(J$2:J9,"●"),"") | L9: =IF(AND(LENB(K9),LENB($B$2),LENB($B$3)),$B$2+$B$3*(K9),"") | M9: =IF(LENB($L9),$B$4&$L9+COLUMN()-COLUMN($M9)&".U = "&G9&CHAR(9)&"'"&M$1,"") | O9: =IF(LENB($L9),$B$4&$L9+COLUMN()-COLUMN($M9)&".U = "&H9&CHAR(9)&"'"&O$1,"") | P9: =IF(LENB($L9),$B$4&$L9+COLUMN()-COLUMN($M9)&".U = "&I9&CHAR(9)&"'"&P$1,"") | Q9: =IF(LENB(K9),IF(1<K9,CHAR(10),"")&"'"&IF(F9=0,"名称未設定",F9)&CHAR(10)&M9&CHAR(10)&O9&CHAR(10)&P9,"")
D10: 8 | E10: =IFERROR(INDEX(title!$A$2:$A$2049,MATCH($D10,title!$C$2:$C$2049,0),1),"") | F10: =IFERROR(INDEX(title!$B$2:$B$2049,MATCH($D10,title!$C$2:$C$2049,0),1),"") | G10: =IFERROR(INDEX(title!$C$2:$C$2049,MATCH($D10,title!$C$2:$C$2049,0),1),"") | H10: =IFERROR(INDEX(title!$D$2:$D$2049,MATCH($D10,title!$C$2:$C$2049,0),1),"") | I10: =IFERROR(INDEX(title!$E$2:$E$2049,MATCH($D10,title!$C$2:$C$2049,0),1),"") | J10: =IF(AND(LENB(G10),0<G10,LENB(H10),0<H10),"●","") | K10: =IF(LENB(J10),COUNTIF(J$2:J10,"●"),"") | L10: =IF(AND(LENB(K10),LENB($B$2),LENB($B$3)),$B$2+$B$3*(K10),"") | M10: =IF(LENB($L10),$B$4&$L10+COLUMN()-COLUMN($M10)&".U = "&G10&CHAR(9)&"'"&M$1,"") | O10: =IF(LENB($L10),$B$4&$L10+COLUMN()-COLUMN($M10)&".U = "&H10&CHAR(9)&"'"&O$1,"") | P10: =IF(LENB($L10),$B$4&$L10+COLUMN()-COLUMN($M10)&".U = "&I10&CHAR(9)&"'"&P$1,"") | Q10: =IF(LENB(K10),IF(1<K10,CHAR(10),"")&"'"&IF(F10=0,"名称未設定",F10)&CHAR(10)&M10&CHAR(10)&O10&CHAR(10)&P10,"")
A11: ファイル | B11: {=CELL("filename")} -> C:\tk\prj\hg-0025-0016\git\kv-x520\doc\[kv_script_conv_TP1_popup.xlsx]title_scripts(変数) | D11: 9 | E11: =IFERROR(INDEX(title!$A$2:$A$2049,MATCH($D11,title!$C$2:$C$2049,0),1),"") | F11: =IFERROR(INDEX(title!$B$2:$B$2049,MATCH($D11,title!$C$2:$C$2049,0),1),"") | G11: =IFERROR(INDEX(title!$C$2:$C$2049,MATCH($D11,title!$C$2:$C$2049,0),1),"") | H11: =IFERROR(INDEX(title!$D$2:$D$2049,MATCH($D11,title!$C$2:$C$2049,0),1),"") | I11: =IFERROR(INDEX(title!$E$2:$E$2049,MATCH($D11,title!$C$2:$C$2049,0),1),"") | J11: =IF(AND(LENB(G11),0<G11,LENB(H11),0<H11),"●","") | K11: =IF(LENB(J11),COUNTIF(J$2:J11,"●"),"") | L11: =IF(AND(LENB(K11),LENB($B$2),LENB($B$3)),$B$2+$B$3*(K11),"") | M11: =IF(LENB($L11),$B$4&$L11+COLUMN()-COLUMN($M11)&".U = "&G11&CHAR(9)&"'"&M$1,"") | O11: =IF(LENB($L11),$B$4&$L11+COLUMN()-COLUMN($M11)&".U = "&H11&CHAR(9)&"'"&O$1,"") | P11: =IF(LENB($L11),$B$4&$L11+COLUMN()-COLUMN($M11)&".U = "&I11&CHAR(9)&"'"&P$1,"") | Q11: =IF(LENB(K11),IF(1<K11,CHAR(10),"")&"'"&IF(F11=0,"名称未設定",F11)&CHAR(10)&M11&CHAR(10)&O11&CHAR(10)&P11,"")
D12: 10 | E12: =IFERROR(INDEX(title!$A$2:$A$2049,MATCH($D12,title!$C$2:$C$2049,0),1),"") | F12: =IFERROR(INDEX(title!$B$2:$B$2049,MATCH($D12,title!$C$2:$C$2049,0),1),"") | G12: =IFERROR(INDEX(title!$C$2:$C$2049,MATCH($D12,title!$C$2:$C$2049,0),1),"") | H12: =IFERROR(INDEX(title!$D$2:$D$2049,MATCH($D12,title!$C$2:$C$2049,0),1),"") | I12: =IFERROR(INDEX(title!$E$2:$E$2049,MATCH($D12,title!$C$2:$C$2049,0),1),"") | J12: =IF(AND(LENB(G12),0<G12,LENB(H12),0<H12),"●","") | K12: =IF(LENB(J12),COUNTIF(J$2:J12,"●"),"") | L12: =IF(AND(LENB(K12),LENB($B$2),LENB($B$3)),$B$2+$B$3*(K12),"") | M12: =IF(LENB($L12),$B$4&$L12+COLUMN()-COLUMN($M12)&".U = "&G12&CHAR(9)&"'"&M$1,"") | O12: =IF(LENB($L12),$B$4&$L12+COLUMN()-COLUMN($M12)&".U = "&H12&CHAR(9)&"'"&O$1,"") | P12: =IF(LENB($L12),$B$4&$L12+COLUMN()-COLUMN($M12)&".U = "&I12&CHAR(9)&"'"&P$1,"") | Q12: =IF(LENB(K12),IF(1<K12,CHAR(10),"")&"'"&IF(F12=0,"名称未設定",F12)&CHAR(10)&M12&CHAR(10)&O12&CHAR(10)&P12,"")
D13: 11 | E13: =IFERROR(INDEX(title!$A$2:$A$2049,MATCH($D13,title!$C$2:$C$2049,0),1),"") | F13: =IFERROR(INDEX(title!$B$2:$B$2049,MATCH($D13,title!$C$2:$C$2049,0),1),"") | G13: =IFERROR(INDEX(title!$C$2:$C$2049,MATCH($D13,title!$C$2:$C$2049,0),1),"") | H13: =IFERROR(INDEX(title!$D$2:$D$2049,MATCH($D13,title!$C$2:$C$2049,0),1),"") | I13: =IFERROR(INDEX(title!$E$2:$E$2049,MATCH($D13,title!$C$2:$C$2049,0),1),"") | J13: =IF(AND(LENB(G13),0<G13,LENB(H13),0<H13),"●","") | K13: =IF(LENB(J13),COUNTIF(J$2:J13,"●"),"") | L13: =IF(AND(LENB(K13),LENB($B$2),LENB($B$3)),$B$2+$B$3*(K13),"") | M13: =IF(LENB($L13),$B$4&$L13+COLUMN()-COLUMN($M13)&".U = "&G13&CHAR(9)&"'"&M$1,"") | O13: =IF(LENB($L13),$B$4&$L13+COLUMN()-COLUMN($M13)&".U = "&H13&CHAR(9)&"'"&O$1,"") | P13: =IF(LENB($L13),$B$4&$L13+COLUMN()-COLUMN($M13)&".U = "&I13&CHAR(9)&"'"&P$1,"") | Q13: =IF(LENB(K13),IF(1<K13,CHAR(10),"")&"'"&IF(F13=0,"名称未設定",F13)&CHAR(10)&M13&CHAR(10)&O13&CHAR(10)&P13,"")
D14: 12 | E14: =IFERROR(INDEX(title!$A$2:$A$2049,MATCH($D14,title!$C$2:$C$2049,0),1),"") | F14: =IFERROR(INDEX(title!$B$2:$B$2049,MATCH($D14,title!$C$2:$C$2049,0),1),"") | G14: =IFERROR(INDEX(title!$C$2:$C$2049,MATCH($D14,title!$C$2:$C$2049,0),1),"") | H14: =IFERROR(INDEX(title!$D$2:$D$2049,MATCH($D14,title!$C$2:$C$2049,0),1),"") | I14: =IFERROR(INDEX(title!$E$2:$E$2049,MATCH($D14,title!$C$2:$C$2049,0),1),"") | J14: =IF(AND(LENB(G14),0<G14,LENB(H14),0<H14),"●","") | K14: =IF(LENB(J14),COUNTIF(J$2:J14,"●"),"") | L14: =IF(AND(LENB(K14),LENB($B$2),LENB($B$3)),$B$2+$B$3*(K14),"") | M14: =IF(LENB($L14),$B$4&$L14+COLUMN()-COLUMN($M14)&".U = "&G14&CHAR(9)&"'"&M$1,"") | O14: =IF(LENB($L14),$B$4&$L14+COLUMN()-COLUMN($M14)&".U = "&H14&CHAR(9)&"'"&O$1,"") | P14: =IF(LENB($L14),$B$4&$L14+COLUMN()-COLUMN($M14)&".U = "&I14&CHAR(9)&"'"&P$1,"") | Q14: =IF(LENB(K14),IF(1<K14,CHAR(10),"")&"'"&IF(F14=0,"名称未設定",F14)&CHAR(10)&M14&CHAR(10)&O14&CHAR(10)&P14,"")
D15: 13 | E15: =IFERROR(INDEX(title!$A$2:$A$2049,MATCH($D15,title!$C$2:$C$2049,0),1),"") | F15: =IFERROR(INDEX(title!$B$2:$B$2049,MATCH($D15,title!$C$2:$C$2049,0),1),"") | G15: =IFERROR(INDEX(title!$C$2:$C$2049,MATCH($D15,title!$C$2:$C$2049,0),1),"") | H15: =IFERROR(INDEX(title!$D$2:$D$2049,MATCH($D15,title!$C$2:$C$2049,0),1),"") | I15: =IFERROR(INDEX(title!$E$2:$E$2049,MATCH($D15,title!$C$2:$C$2049,0),1),"") | J15: =IF(AND(LENB(G15),0<G15,LENB(H15),0<H15),"●","") | K15: =IF(LENB(J15),COUNTIF(J$2:J15,"●"),"") | L15: =IF(AND(LENB(K15),LENB($B$2),LENB($B$3)),$B$2+$B$3*(K15),"") | M15: =IF(LENB($L15),$B$4&$L15+COLUMN()-COLUMN($M15)&".U = "&G15&CHAR(9)&"'"&M$1,"") | O15: =IF(LENB($L15),$B$4&$L15+COLUMN()-COLUMN($M15)&".U = "&H15&CHAR(9)&"'"&O$1,"") | P15: =IF(LENB($L15),$B$4&$L15+COLUMN()-COLUMN($M15)&".U = "&I15&CHAR(9)&"'"&P$1,"") | Q15: =IF(LENB(K15),IF(1<K15,CHAR(10),"")&"'"&IF(F15=0,"名称未設定",F15)&CHAR(10)&M15&CHAR(10)&O15&CHAR(10)&P15,"")
D16: 14 | E16: =IFERROR(INDEX(title!$A$2:$A$2049,MATCH($D16,title!$C$2:$C$2049,0),1),"") | F16: =IFERROR(INDEX(title!$B$2:$B$2049,MATCH($D16,title!$C$2:$C$2049,0),1),"") | G16: =IFERROR(INDEX(title!$C$2:$C$2049,MATCH($D16,title!$C$2:$C$2049,0),1),"") | H16: =IFERROR(INDEX(title!$D$2:$D$2049,MATCH($D16,title!$C$2:$C$2049,0),1),"") | I16: =IFERROR(INDEX(title!$E$2:$E$2049,MATCH($D16,title!$C$2:$C$2049,0),1),"") | J16: =IF(AND(LENB(G16),0<G16,LENB(H16),0<H16),"●","") | K16: =IF(LENB(J16),COUNTIF(J$2:J16,"●"),"") | L16: =IF(AND(LENB(K16),LENB($B$2),LENB($B$3)),$B$2+$B$3*(K16),"") | M16: =IF(LENB($L16),$B$4&$L16+COLUMN()-COLUMN($M16)&".U = "&G16&CHAR(9)&"'"&M$1,"") | O16: =IF(LENB($L16),$B$4&$L16+COLUMN()-COLUMN($M16)&".U = "&H16&CHAR(9)&"'"&O$1,"") | P16: =IF(LENB($L16),$B$4&$L16+COLUMN()-COLUMN($M16)&".U = "&I16&CHAR(9)&"'"&P$1,"") | Q16: =IF(LENB(K16),IF(1<K16,CHAR(10),"")&"'"&IF(F16=0,"名称未設定",F16)&CHAR(10)&M16&CHAR(10)&O16&CHAR(10)&P16,"")
D17: 15 | E17: =IFERROR(INDEX(title!$A$2:$A$2049,MATCH($D17,title!$C$2:$C$2049,0),1),"") | F17: =IFERROR(INDEX(title!$B$2:$B$2049,MATCH($D17,title!$C$2:$C$2049,0),1),"") | G17: =IFERROR(INDEX(title!$C$2:$C$2049,MATCH($D17,title!$C$2:$C$2049,0),1),"") | H17: =IFERROR(INDEX(title!$D$2:$D$2049,MATCH($D17,title!$C$2:$C$2049,0),1),"") | I17: =IFERROR(INDEX(title!$E$2:$E$2049,MATCH($D17,title!$C$2:$C$2049,0),1),"") | J17: =IF(AND(LENB(G17),0<G17,LENB(H17),0<H17),"●","") | K17: =IF(LENB(J17),COUNTIF(J$2:J17,"●"),"") | L17: =IF(AND(LENB(K17),LENB($B$2),LENB($B$3)),$B$2+$B$3*(K17),"") | M17: =IF(LENB($L17),$B$4&$L17+COLUMN()-COLUMN($M17)&".U = "&G17&CHAR(9)&"'"&M$1,"") | O17: =IF(LENB($L17),$B$4&$L17+COLUMN()-COLUMN($M17)&".U = "&H17&CHAR(9)&"'"&O$1,"") | P17: =IF(LENB($L17),$B$4&$L17+COLUMN()-COLUMN($M17)&".U = "&I17&CHAR(9)&"'"&P$1,"") | Q17: =IF(LENB(K17),IF(1<K17,CHAR(10),"")&"'"&IF(F17=0,"名称未設定",F17)&CHAR(10)&M17&CHAR(10)&O17&CHAR(10)&P17,"")
D18: 16 | E18: =IFERROR(INDEX(title!$A$2:$A$2049,MATCH($D18,title!$C$2:$C$2049,0),1),"") | F18: =IFERROR(INDEX(title!$B$2:$B$2049,MATCH($D18,title!$C$2:$C$2049,0),1),"") | G18: =IFERROR(INDEX(title!$C$2:$C$2049,MATCH($D18,title!$C$2:$C$2049,0),1),"") | H18: =IFERROR(INDEX(title!$D$2:$D$2049,MATCH($D18,title!$C$2:$C$2049,0),1),"") | I18: =IFERROR(INDEX(title!$E$2:$E$2049,MATCH($D18,title!$C$2:$C$2049,0),1),"") | J18: =IF(AND(LENB(G18),0<G18,LENB(H18),0<H18),"●","") | K18: =IF(LENB(J18),COUNTIF(J$2:J18,"●"),"") | L18: =IF(AND(LENB(K18),LENB($B$2),LENB($B$3)),$B$2+$B$3*(K18),"") | M18: =IF(LENB($L18),$B$4&$L18+COLUMN()-COLUMN($M18)&".U = "&G18&CHAR(9)&"'"&M$1,"") | O18: =IF(LENB($L18),$B$4&$L18+COLUMN()-COLUMN($M18)&".U = "&H18&CHAR(9)&"'"&O$1,"") | P18: =IF(LENB($L18),$B$4&$L18+COLUMN()-COLUMN($M18)&".U = "&I18&CHAR(9)&"'"&P$1,"") | Q18: =IF(LENB(K18),IF(1<K18,CHAR(10),"")&"'"&IF(F18=0,"名称未設定",F18)&CHAR(10)&M18&CHAR(10)&O18&CHAR(10)&P18,"")
D19: 17 | E19: =IFERROR(INDEX(title!$A$2:$A$2049,MATCH($D19,title!$C$2:$C$2049,0),1),"") | F19: =IFERROR(INDEX(title!$B$2:$B$2049,MATCH($D19,title!$C$2:$C$2049,0),1),"") | G19: =IFERROR(INDEX(title!$C$2:$C$2049,MATCH($D19,title!$C$2:$C$2049,0),1),"") | H19: =IFERROR(INDEX(title!$D$2:$D$2049,MATCH($D19,title!$C$2:$C$2049,0),1),"") | I19: =IFERROR(INDEX(title!$E$2:$E$2049,MATCH($D19,title!$C$2:$C$2049,0),1),"") | J19: =IF(AND(LENB(G19),0<G19,LENB(H19),0<H19),"●","") | K19: =IF(LENB(J19),COUNTIF(J$2:J19,"●"),"") | L19: =IF(AND(LENB(K19),LENB($B$2),LENB($B$3)),$B$2+$B$3*(K19),"") | M19: =IF(LENB($L19),$B$4&$L19+COLUMN()-COLUMN($M19)&".U = "&G19&CHAR(9)&"'"&M$1,"") | O19: =IF(LENB($L19),$B$4&$L19+COLUMN()-COLUMN($M19)&".U = "&H19&CHAR(9)&"'"&O$1,"") | P19: =IF(LENB($L19),$B$4&$L19+COLUMN()-COLUMN($M19)&".U = "&I19&CHAR(9)&"'"&P$1,"") | Q19: =IF(LENB(K19),IF(1<K19,CHAR(10),"")&"'"&IF(F19=0,"名称未設定",F19)&CHAR(10)&M19&CHAR(10)&O19&CHAR(10)&P19,"")
D20: 18 | E20: =IFERROR(INDEX(title!$A$2:$A$2049,MATCH($D20,title!$C$2:$C$2049,0),1),"") | F20: =IFERROR(INDEX(title!$B$2:$B$2049,MATCH($D20,title!$C$2:$C$2049,0),1),"") | G20: =IFERROR(INDEX(title!$C$2:$C$2049,MATCH($D20,title!$C$2:$C$2049,0),1),"") | H20: =IFERROR(INDEX(title!$D$2:$D$2049,MATCH($D20,title!$C$2:$C$2049,0),1),"") | I20: =IFERROR(INDEX(title!$E$2:$E$2049,MATCH($D20,title!$C$2:$C$2049,0),1),"") | J20: =IF(AND(LENB(G20),0<G20,LENB(H20),0<H20),"●","") | K20: =IF(LENB(J20),COUNTIF(J$2:J20,"●"),"") | L20: =IF(AND(LENB(K20),LENB($B$2),LENB($B$3)),$B$2+$B$3*(K20),"") | M20: =IF(LENB($L20),$B$4&$L20+COLUMN()-COLUMN($M20)&".U = "&G20&CHAR(9)&"'"&M$1,"") | O20: =IF(LENB($L20),$B$4&$L20+COLUMN()-COLUMN($M20)&".U = "&H20&CHAR(9)&"'"&O$1,"") | P20: =IF(LENB($L20),$B$4&$L20+COLUMN()-COLUMN($M20)&".U = "&I20&CHAR(9)&"'"&P$1,"") | Q20: =IF(LENB(K20),IF(1<K20,CHAR(10),"")&"'"&IF(F20=0,"名称未設定",F20)&CHAR(10)&M20&CHAR(10)&O20&CHAR(10)&P20,"")
A21: 生成script | B21: =$Q$2052 -> 'このスクリプトは C:\tk\prj\hg-0025-0016\git\kv-x520\doc\[kv_script_conv_TP1_popup.xlsx]title_scripts(変数) によって生成されました。 '軸1 タイトル DM8264.U = 1000 'ウィンドウNo. DM8266.U = 800 '幅 DM8267.U = 32 '高さ '軸2 タイトル DM8268.U = 1005 'ウィンドウNo. DM8270.U = 800 '幅 DM8271.U = 32 '高さ '軸3 タイトル DM8272.U = 1010 'ウィンドウNo. DM8274.U = 800 '幅 DM8275.U = 32 '高さ '軸4 タイトル DM8276.U = 1015 'ウィンドウNo. DM8278.U = 800 '幅 DM8279.U = 32 '高さ '軸5 タイトル DM8280.U = 1020 'ウィンドウNo. DM8282.U = 800 '幅 DM8283.U = 32 '高さ '軸6 タイトル DM8284.U = 1025 'ウィンドウNo. DM8286.U = 800 '幅 DM8287.U = 32 '高さ '軸7 タイトル DM8288.U = 1030 'ウィンドウNo. DM8290.U = 800 '幅 DM8291.U = 32 '高さ '軸8 タイトル DM8292.U = 1035 'ウィンドウNo. DM8294.U = 800 '幅 DM8295.U = 32 '高さ '軸9 タイトル DM8296.U = 1040 'ウィンドウNo. DM8298.U = 800 '幅 DM8299.U = 32 '高さ '軸10 タイトル DM8300.U = 1045 'ウィンドウNo. DM8302.U = 800 '幅 DM8303.U = 32 '高さ '軸11 タイトル DM8304.U = 1050 'ウィンドウNo. DM8306.U = 800 '幅 DM8307.U = 32 '高さ '軸12 タイトル DM8308.U = 1055 'ウィンドウNo. DM8310.U = 800 '幅 DM8311.U = 32 '高さ '軸13 タイトル DM8312.U = 1060 'ウィンドウNo. DM8314.U = 800 '幅 DM8315.U = 32 '高さ '軸14 タイトル DM8316.U = 1065 'ウィンドウNo. DM8318.U = 800 '幅 DM8319.U = 32 '高さ '軸15 タイトル DM8320.U = 1070 'ウィンドウNo. DM8322.U = 800 '幅 DM8323.U = 32 '高さ '軸16 タイトル DM8324.U = 1075 'ウィンドウNo. DM8326.U = 800 '幅 DM8327.U = 32 '高さ 'シリンダ1 タイトル DM8328.U = 1100 'ウィンドウNo. DM8330.U = 800 '幅 DM8331.U = 32 '高さ 'シリンダ2 タイトル DM8332.U = 1104 'ウィンドウNo. DM8334.U = 800 '幅 DM8335.U = 32 '高さ 'シリンダ3 タイトル DM8336.U = 1108 'ウィンドウNo. DM8338.U = 800 '幅 DM8339.U = 32 '高さ 'シリンダ4 タイトル DM8340.U = 1112 'ウィンドウNo. DM8342.U = 800 '幅 DM8343.U = 32 '高さ 'シリンダ5 タイトル DM8344.U = 1116 'ウィンドウNo. DM8346.U = 800 '幅 DM8347.U = 32 '高さ 'シリンダ6 タイトル DM8348.U = 1120 'ウィンドウNo. DM8350.U = 800 '幅 DM8351.U = 32 '高さ 'シリンダ7 タイトル DM8352.U = 1124 'ウィンドウNo. DM8354.U = 800 '幅 DM8355.U = 32 '高さ 'シリンダ8 タイトル DM8356.U = 1128 'ウィンドウNo. DM8358.U = 800 '幅 DM8359.U = 32 '高さ 'シリンダ9 タイトル DM8360.U = 1132 'ウィンドウNo. DM8362.U = 800 '幅 DM8363.U = 32 '高さ 'シリンダ10 タイトル DM8364.U = 1136 'ウィンドウNo. DM8366.U = 800 '幅 DM8367.U = 32 '高さ 'シリンダ11 タイトル DM8368.U = 1140 'ウィンドウNo. DM8370.U = 800 '幅 DM8371.U = 32 '高さ 'シリンダ12 タイトル DM8372.U = 1144 'ウィンドウNo. DM8374.U = 800 '幅 DM8375.U = 32 '高さ 'シリンダ13 タイトル DM8376.U = 1148 'ウィンドウNo. DM8378.U = 800 '幅 DM8379.U = 32 '高さ 'シリンダ14 タイトル DM8380.U = 1152 'ウィンドウNo. DM8382.U = 800 '幅 DM8383.U = 32 '高さ 'シリンダ15 タイトル DM8384.U = 1156 'ウィンドウNo. DM8386.U = 800 '幅 DM8387.U = 32 '高さ 'シリンダ16 タイトル DM8388.U = 1160 'ウィンドウNo. DM8390.U = 800 '幅 DM8391.U = 32 '高さ 'シリンダ17 タイトル DM8392.U = 1164 'ウィンドウNo. DM8394.U = 800 '幅 DM8395.U = 32 '高さ 'シリンダ18 タイトル DM8396.U = 1168 'ウィンドウNo. DM8398.U = 800 '幅 DM8399.U = 32 '高さ 'シリンダ19 タイトル DM8400.U = 1172 'ウィンドウNo. DM8402.U = 800 '幅 DM8403.U = 32 '高さ 'エレシリ1 タイトル DM8404.U = 1200 'ウィンドウNo. DM8406.U = 800 '幅 DM8407.U = 32 '高さ '合計ウィンドウ数 DM8260 = 36 '-----ここまで生成script----- | D21: 19 | E21: =IFERROR(INDEX(title!$A$2:$A$2049,MATCH($D21,title!$C$2:$C$2049,0),1),"") | F21: =IFERROR(INDEX(title!$B$2:$B$2049,MATCH($D21,title!$C$2:$C$2049,0),1),"") | G21: =IFERROR(INDEX(title!$C$2:$C$2049,MATCH($D21,title!$C$2:$C$2049,0),1),"") | H21: =IFERROR(INDEX(title!$D$2:$D$2049,MATCH($D21,title!$C$2:$C$2049,0),1),"") | I21: =IFERROR(INDEX(title!$E$2:$E$2049,MATCH($D21,title!$C$2:$C$2049,0),1),"") | J21: =IF(AND(LENB(G21),0<G21,LENB(H21),0<H21),"●","") | K21: =IF(LENB(J21),COUNTIF(J$2:J21,"●"),"") | L21: =IF(AND(LENB(K21),LENB($B$2),LENB($B$3)),$B$2+$B$3*(K21),"") | M21: =IF(LENB($L21),$B$4&$L21+COLUMN()-COLUMN($M21)&".U = "&G21&CHAR(9)&"'"&M$1,"") | O21: =IF(LENB($L21),$B$4&$L21+COLUMN()-COLUMN($M21)&".U = "&H21&CHAR(9)&"'"&O$1,"") | P21: =IF(LENB($L21),$B$4&$L21+COLUMN()-COLUMN($M21)&".U = "&I21&CHAR(9)&"'"&P$1,"") | Q21: =IF(LENB(K21),IF(1<K21,CHAR(10),"")&"'"&IF(F21=0,"名称未設定",F21)&CHAR(10)&M21&CHAR(10)&O21&CHAR(10)&P21,"")
D22: 20 | E22: =IFERROR(INDEX(title!$A$2:$A$2049,MATCH($D22,title!$C$2:$C$2049,0),1),"") | F22: =IFERROR(INDEX(title!$B$2:$B$2049,MATCH($D22,title!$C$2:$C$2049,0),1),"") | G22: =IFERROR(INDEX(title!$C$2:$C$2049,MATCH($D22,title!$C$2:$C$2049,0),1),"") | H22: =IFERROR(INDEX(title!$D$2:$D$2049,MATCH($D22,title!$C$2:$C$2049,0),1),"") | I22: =IFERROR(INDEX(title!$E$2:$E$2049,MATCH($D22,title!$C$2:$C$2049,0),1),"") | J22: =IF(AND(LENB(G22),0<G22,LENB(H22),0<H22),"●","") | K22: =IF(LENB(J22),COUNTIF(J$2:J22,"●"),"") | L22: =IF(AND(LENB(K22),LENB($B$2),LENB($B$3)),$B$2+$B$3*(K22),"") | M22: =IF(LENB($L22),$B$4&$L22+COLUMN()-COLUMN($M22)&".U = "&G22&CHAR(9)&"'"&M$1,"") | O22: =IF(LENB($L22),$B$4&$L22+COLUMN()-COLUMN($M22)&".U = "&H22&CHAR(9)&"'"&O$1,"") | P22: =IF(LENB($L22),$B$4&$L22+COLUMN()-COLUMN($M22)&".U = "&I22&CHAR(9)&"'"&P$1,"") | Q22: =IF(LENB(K22),IF(1<K22,CHAR(10),"")&"'"&IF(F22=0,"名称未設定",F22)&CHAR(10)&M22&CHAR(10)&O22&CHAR(10)&P22,"")
D23: 21 | E23: =IFERROR(INDEX(title!$A$2:$A$2049,MATCH($D23,title!$C$2:$C$2049,0),1),"") | F23: =IFERROR(INDEX(title!$B$2:$B$2049,MATCH($D23,title!$C$2:$C$2049,0),1),"") | G23: =IFERROR(INDEX(title!$C$2:$C$2049,MATCH($D23,title!$C$2:$C$2049,0),1),"") | H23: =IFERROR(INDEX(title!$D$2:$D$2049,MATCH($D23,title!$C$2:$C$2049,0),1),"") | I23: =IFERROR(INDEX(title!$E$2:$E$2049,MATCH($D23,title!$C$2:$C$2049,0),1),"") | J23: =IF(AND(LENB(G23),0<G23,LENB(H23),0<H23),"●","") | K23: =IF(LENB(J23),COUNTIF(J$2:J23,"●"),"") | L23: =IF(AND(LENB(K23),LENB($B$2),LENB($B$3)),$B$2+$B$3*(K23),"") | M23: =IF(LENB($L23),$B$4&$L23+COLUMN()-COLUMN($M23)&".U = "&G23&CHAR(9)&"'"&M$1,"") | O23: =IF(LENB($L23),$B$4&$L23+COLUMN()-COLUMN($M23)&".U = "&H23&CHAR(9)&"'"&O$1,"") | P23: =IF(LENB($L23),$B$4&$L23+COLUMN()-COLUMN($M23)&".U = "&I23&CHAR(9)&"'"&P$1,"") | Q23: =IF(LENB(K23),IF(1<K23,CHAR(10),"")&"'"&IF(F23=0,"名称未設定",F23)&CHAR(10)&M23&CHAR(10)&O23&CHAR(10)&P23,"")
D24: 22 | E24: =IFERROR(INDEX(title!$A$2:$A$2049,MATCH($D24,title!$C$2:$C$2049,0),1),"") | F24: =IFERROR(INDEX(title!$B$2:$B$2049,MATCH($D24,title!$C$2:$C$2049,0),1),"") | G24: =IFERROR(INDEX(title!$C$2:$C$2049,MATCH($D24,title!$C$2:$C$2049,0),1),"") | H24: =IFERROR(INDEX(title!$D$2:$D$2049,MATCH($D24,title!$C$2:$C$2049,0),1),"") | I24: =IFERROR(INDEX(title!$E$2:$E$2049,MATCH($D24,title!$C$2:$C$2049,0),1),"") | J24: =IF(AND(LENB(G24),0<G24,LENB(H24),0<H24),"●","") | K24: =IF(LENB(J24),COUNTIF(J$2:J24,"●"),"") | L24: =IF(AND(LENB(K24),LENB($B$2),LENB($B$3)),$B$2+$B$3*(K24),"") | M24: =IF(LENB($L24),$B$4&$L24+COLUMN()-COLUMN($M24)&".U = "&G24&CHAR(9)&"'"&M$1,"") | O24: =IF(LENB($L24),$B$4&$L24+COLUMN()-COLUMN($M24)&".U = "&H24&CHAR(9)&"'"&O$1,"") | P24: =IF(LENB($L24),$B$4&$L24+COLUMN()-COLUMN($M24)&".U = "&I24&CHAR(9)&"'"&P$1,"") | Q24: =IF(LENB(K24),IF(1<K24,CHAR(10),"")&"'"&IF(F24=0,"名称未設定",F24)&CHAR(10)&M24&CHAR(10)&O24&CHAR(10)&P24,"")
D25: 23 | E25: =IFERROR(INDEX(title!$A$2:$A$2049,MATCH($D25,title!$C$2:$C$2049,0),1),"") | F25: =IFERROR(INDEX(title!$B$2:$B$2049,MATCH($D25,title!$C$2:$C$2049,0),1),"") | G25: =IFERROR(INDEX(title!$C$2:$C$2049,MATCH($D25,title!$C$2:$C$2049,0),1),"") | H25: =IFERROR(INDEX(title!$D$2:$D$2049,MATCH($D25,title!$C$2:$C$2049,0),1),"") | I25: =IFERROR(INDEX(title!$E$2:$E$2049,MATCH($D25,title!$C$2:$C$2049,0),1),"") | J25: =IF(AND(LENB(G25),0<G25,LENB(H25),0<H25),"●","") | K25: =IF(LENB(J25),COUNTIF(J$2:J25,"●"),"") | L25: =IF(AND(LENB(K25),LENB($B$2),LENB($B$3)),$B$2+$B$3*(K25),"") | M25: =IF(LENB($L25),$B$4&$L25+COLUMN()-COLUMN($M25)&".U = "&G25&CHAR(9)&"'"&M$1,"") | O25: =IF(LENB($L25),$B$4&$L25+COLUMN()-COLUMN($M25)&".U = "&H25&CHAR(9)&"'"&O$1,"") | P25: =IF(LENB($L25),$B$4&$L25+COLUMN()-COLUMN($M25)&".U = "&I25&CHAR(9)&"'"&P$1,"") | Q25: =IF(LENB(K25),IF(1<K25,CHAR(10),"")&"'"&IF(F25=0,"名称未設定",F25)&CHAR(10)&M25&CHAR(10)&O25&CHAR(10)&P25,"")
D26: 24 | E26: =IFERROR(INDEX(title!$A$2:$A$2049,MATCH($D26,title!$C$2:$C$2049,0),1),"") | F26: =IFERROR(INDEX(title!$B$2:$B$2049,MATCH($D26,title!$C$2:$C$2049,0),1),"") | G26: =IFERROR(INDEX(title!$C$2:$C$2049,MATCH($D26,title!$C$2:$C$2049,0),1),"") | H26: =IFERROR(INDEX(title!$D$2:$D$2049,MATCH($D26,title!$C$2:$C$2049,0),1),"") | I26: =IFERROR(INDEX(title!$E$2:$E$2049,MATCH($D26,title!$C$2:$C$2049,0),1),"") | J26: =IF(AND(LENB(G26),0<G26,LENB(H26),0<H26),"●","") | K26: =IF(LENB(J26),COUNTIF(J$2:J26,"●"),"") | L26: =IF(AND(LENB(K26),LENB($B$2),LENB($B$3)),$B$2+$B$3*(K26),"") | M26: =IF(LENB($L26),$B$4&$L26+COLUMN()-COLUMN($M26)&".U = "&G26&CHAR(9)&"'"&M$1,"") | O26: =IF(LENB($L26),$B$4&$L26+COLUMN()-COLUMN($M26)&".U = "&H26&CHAR(9)&"'"&O$1,"") | P26: =IF(LENB($L26),$B$4&$L26+COLUMN()-COLUMN($M26)&".U = "&I26&CHAR(9)&"'"&P$1,"") | Q26: =IF(LENB(K26),IF(1<K26,CHAR(10),"")&"'"&IF(F26=0,"名称未設定",F26)&CHAR(10)&M26&CHAR(10)&O26&CHAR(10)&P26,"")
D27: 25 | E27: =IFERROR(INDEX(title!$A$2:$A$2049,MATCH($D27,title!$C$2:$C$2049,0),1),"") | F27: =IFERROR(INDEX(title!$B$2:$B$2049,MATCH($D27,title!$C$2:$C$2049,0),1),"") | G27: =IFERROR(INDEX(title!$C$2:$C$2049,MATCH($D27,title!$C$2:$C$2049,0),1),"") | H27: =IFERROR(INDEX(title!$D$2:$D$2049,MATCH($D27,title!$C$2:$C$2049,0),1),"") | I27: =IFERROR(INDEX(title!$E$2:$E$2049,MATCH($D27,title!$C$2:$C$2049,0),1),"") | J27: =IF(AND(LENB(G27),0<G27,LENB(H27),0<H27),"●","") | K27: =IF(LENB(J27),COUNTIF(J$2:J27,"●"),"") | L27: =IF(AND(LENB(K27),LENB($B$2),LENB($B$3)),$B$2+$B$3*(K27),"") | M27: =IF(LENB($L27),$B$4&$L27+COLUMN()-COLUMN($M27)&".U = "&G27&CHAR(9)&"'"&M$1,"") | O27: =IF(LENB($L27),$B$4&$L27+COLUMN()-COLUMN($M27)&".U = "&H27&CHAR(9)&"'"&O$1,"") | P27: =IF(LENB($L27),$B$4&$L27+COLUMN()-COLUMN($M27)&".U = "&I27&CHAR(9)&"'"&P$1,"") | Q27: =IF(LENB(K27),IF(1<K27,CHAR(10),"")&"'"&IF(F27=0,"名称未設定",F27)&CHAR(10)&M27&CHAR(10)&O27&CHAR(10)&P27,"")
D28: 26 | E28: =IFERROR(INDEX(title!$A$2:$A$2049,MATCH($D28,title!$C$2:$C$2049,0),1),"") | F28: =IFERROR(INDEX(title!$B$2:$B$2049,MATCH($D28,title!$C$2:$C$2049,0),1),"") | G28: =IFERROR(INDEX(title!$C$2:$C$2049,MATCH($D28,title!$C$2:$C$2049,0),1),"") | H28: =IFERROR(INDEX(title!$D$2:$D$2049,MATCH($D28,title!$C$2:$C$2049,0),1),"") | I28: =IFERROR(INDEX(title!$E$2:$E$2049,MATCH($D28,title!$C$2:$C$2049,0),1),"") | J28: =IF(AND(LENB(G28),0<G28,LENB(H28),0<H28),"●","") | K28: =IF(LENB(J28),COUNTIF(J$2:J28,"●"),"") | L28: =IF(AND(LENB(K28),LENB($B$2),LENB($B$3)),$B$2+$B$3*(K28),"") | M28: =IF(LENB($L28),$B$4&$L28+COLUMN()-COLUMN($M28)&".U = "&G28&CHAR(9)&"'"&M$1,"") | O28: =IF(LENB($L28),$B$4&$L28+COLUMN()-COLUMN($M28)&".U = "&H28&CHAR(9)&"'"&O$1,"") | P28: =IF(LENB($L28),$B$4&$L28+COLUMN()-COLUMN($M28)&".U = "&I28&CHAR(9)&"'"&P$1,"") | Q28: =IF(LENB(K28),IF(1<K28,CHAR(10),"")&"'"&IF(F28=0,"名称未設定",F28)&CHAR(10)&M28&CHAR(10)&O28&CHAR(10)&P28,"")
D29: 27 | E29: =IFERROR(INDEX(title!$A$2:$A$2049,MATCH($D29,title!$C$2:$C$2049,0),1),"") | F29: =IFERROR(INDEX(title!$B$2:$B$2049,MATCH($D29,title!$C$2:$C$2049,0),1),"") | G29: =IFERROR(INDEX(title!$C$2:$C$2049,MATCH($D29,title!$C$2:$C$2049,0),1),"") | H29: =IFERROR(INDEX(title!$D$2:$D$2049,MATCH($D29,title!$C$2:$C$2049,0),1),"") | I29: =IFERROR(INDEX(title!$E$2:$E$2049,MATCH($D29,title!$C$2:$C$2049,0),1),"") | J29: =IF(AND(LENB(G29),0<G29,LENB(H29),0<H29),"●","") | K29: =IF(LENB(J29),COUNTIF(J$2:J29,"●"),"") | L29: =IF(AND(LENB(K29),LENB($B$2),LENB($B$3)),$B$2+$B$3*(K29),"") | M29: =IF(LENB($L29),$B$4&$L29+COLUMN()-COLUMN($M29)&".U = "&G29&CHAR(9)&"'"&M$1,"") | O29: =IF(LENB($L29),$B$4&$L29+COLUMN()-COLUMN($M29)&".U = "&H29&CHAR(9)&"'"&O$1,"") | P29: =IF(LENB($L29),$B$4&$L29+COLUMN()-COLUMN($M29)&".U = "&I29&CHAR(9)&"'"&P$1,"") | Q29: =IF(LENB(K29),IF(1<K29,CHAR(10),"")&"'"&IF(F29=0,"名称未設定",F29)&CHAR(10)&M29&CHAR(10)&O29&CHAR(10)&P29,"")
D30: 28 | E30: =IFERROR(INDEX(title!$A$2:$A$2049,MATCH($D30,title!$C$2:$C$2049,0),1),"") | F30: =IFERROR(INDEX(title!$B$2:$B$2049,MATCH($D30,title!$C$2:$C$2049,0),1),"") | G30: =IFERROR(INDEX(title!$C$2:$C$2049,MATCH($D30,title!$C$2:$C$2049,0),1),"") | H30: =IFERROR(INDEX(title!$D$2:$D$2049,MATCH($D30,title!$C$2:$C$2049,0),1),"") | I30: =IFERROR(INDEX(title!$E$2:$E$2049,MATCH($D30,title!$C$2:$C$2049,0),1),"") | J30: =IF(AND(LENB(G30),0<G30,LENB(H30),0<H30),"●","") | K30: =IF(LENB(J30),COUNTIF(J$2:J30,"●"),"") | L30: =IF(AND(LENB(K30),LENB($B$2),LENB($B$3)),$B$2+$B$3*(K30),"") | M30: =IF(LENB($L30),$B$4&$L30+COLUMN()-COLUMN($M30)&".U = "&G30&CHAR(9)&"'"&M$1,"") | O30: =IF(LENB($L30),$B$4&$L30+COLUMN()-COLUMN($M30)&".U = "&H30&CHAR(9)&"'"&O$1,"") | P30: =IF(LENB($L30),$B$4&$L30+COLUMN()-COLUMN($M30)&".U = "&I30&CHAR(9)&"'"&P$1,"") | Q30: =IF(LENB(K30),IF(1<K30,CHAR(10),"")&"'"&IF(F30=0,"名称未設定",F30)&CHAR(10)&M30&CHAR(10)&O30&CHAR(10)&P30,"")
D31: 29 | E31: =IFERROR(INDEX(title!$A$2:$A$2049,MATCH($D31,title!$C$2:$C$2049,0),1),"") | F31: =IFERROR(INDEX(title!$B$2:$B$2049,MATCH($D31,title!$C$2:$C$2049,0),1),"") | G31: =IFERROR(INDEX(title!$C$2:$C$2049,MATCH($D31,title!$C$2:$C$2049,0),1),"") | H31: =IFERROR(INDEX(title!$D$2:$D$2049,MATCH($D31,title!$C$2:$C$2049,0),1),"") | I31: =IFERROR(INDEX(title!$E$2:$E$2049,MATCH($D31,title!$C$2:$C$2049,0),1),"") | J31: =IF(AND(LENB(G31),0<G31,LENB(H31),0<H31),"●","") | K31: =IF(LENB(J31),COUNTIF(J$2:J31,"●"),"") | L31: =IF(AND(LENB(K31),LENB($B$2),LENB($B$3)),$B$2+$B$3*(K31),"") | M31: =IF(LENB($L31),$B$4&$L31+COLUMN()-COLUMN($M31)&".U = "&G31&CHAR(9)&"'"&M$1,"") | O31: =IF(LENB($L31),$B$4&$L31+COLUMN()-COLUMN($M31)&".U = "&H31&CHAR(9)&"'"&O$1,"") | P31: =IF(LENB($L31),$B$4&$L31+COLUMN()-COLUMN($M31)&".U = "&I31&CHAR(9)&"'"&P$1,"") | Q31: =IF(LENB(K31),IF(1<K31,CHAR(10),"")&"'"&IF(F31=0,"名称未設定",F31)&CHAR(10)&M31&CHAR(10)&O31&CHAR(10)&P31,"")
D32: 30 | E32: =IFERROR(INDEX(title!$A$2:$A$2049,MATCH($D32,title!$C$2:$C$2049,0),1),"") | F32: =IFERROR(INDEX(title!$B$2:$B$2049,MATCH($D32,title!$C$2:$C$2049,0),1),"") | G32: =IFERROR(INDEX(title!$C$2:$C$2049,MATCH($D32,title!$C$2:$C$2049,0),1),"") | H32: =IFERROR(INDEX(title!$D$2:$D$2049,MATCH($D32,title!$C$2:$C$2049,0),1),"") | I32: =IFERROR(INDEX(title!$E$2:$E$2049,MATCH($D32,title!$C$2:$C$2049,0),1),"") | J32: =IF(AND(LENB(G32),0<G32,LENB(H32),0<H32),"●","") | K32: =IF(LENB(J32),COUNTIF(J$2:J32,"●"),"") | L32: =IF(AND(LENB(K32),LENB($B$2),LENB($B$3)),$B$2+$B$3*(K32),"") | M32: =IF(LENB($L32),$B$4&$L32+COLUMN()-COLUMN($M32)&".U = "&G32&CHAR(9)&"'"&M$1,"") | O32: =IF(LENB($L32),$B$4&$L32+COLUMN()-COLUMN($M32)&".U = "&H32&CHAR(9)&"'"&O$1,"") | P32: =IF(LENB($L32),$B$4&$L32+COLUMN()-COLUMN($M32)&".U = "&I32&CHAR(9)&"'"&P$1,"") | Q32: =IF(LENB(K32),IF(1<K32,CHAR(10),"")&"'"&IF(F32=0,"名称未設定",F32)&CHAR(10)&M32&CHAR(10)&O32&CHAR(10)&P32,"")
D33: 31 | E33: =IFERROR(INDEX(title!$A$2:$A$2049,MATCH($D33,title!$C$2:$C$2049,0),1),"") | F33: =IFERROR(INDEX(title!$B$2:$B$2049,MATCH($D33,title!$C$2:$C$2049,0),1),"") | G33: =IFERROR(INDEX(title!$C$2:$C$2049,MATCH($D33,title!$C$2:$C$2049,0),1),"") | H33: =IFERROR(INDEX(title!$D$2:$D$2049,MATCH($D33,title!$C$2:$C$2049,0),1),"") | I33: =IFERROR(INDEX(title!$E$2:$E$2049,MATCH($D33,title!$C$2:$C$2049,0),1),"") | J33: =IF(AND(LENB(G33),0<G33,LENB(H33),0<H33),"●","") | K33: =IF(LENB(J33),COUNTIF(J$2:J33,"●"),"") | L33: =IF(AND(LENB(K33),LENB($B$2),LENB($B$3)),$B$2+$B$3*(K33),"") | M33: =IF(LENB($L33),$B$4&$L33+COLUMN()-COLUMN($M33)&".U = "&G33&CHAR(9)&"'"&M$1,"") | O33: =IF(LENB($L33),$B$4&$L33+COLUMN()-COLUMN($M33)&".U = "&H33&CHAR(9)&"'"&O$1,"") | P33: =IF(LENB($L33),$B$4&$L33+COLUMN()-COLUMN($M33)&".U = "&I33&CHAR(9)&"'"&P$1,"") | Q33: =IF(LENB(K33),IF(1<K33,CHAR(10),"")&"'"&IF(F33=0,"名称未設定",F33)&CHAR(10)&M33&CHAR(10)&O33&CHAR(10)&P33,"")
... D2049: 2047 | E2049: =IFERROR(INDEX(title!$A$2:$A$2049,MATCH($D2049,title!$C$2:$C$2049,0),1),"") | F2049: =IFERROR(INDEX(title!$B$2:$B$2049,MATCH($D2049,title!$C$2:$C$2049,0),1),"") | G2049: =IFERROR(INDEX(title!$C$2:$C$2049,MATCH($D2049,title!$C$2:$C$2049,0),1),"") | H2049: =IFERROR(INDEX(title!$D$2:$D$2049,MATCH($D2049,title!$C$2:$C$2049,0),1),"") | I2049: =IFERROR(INDEX(title!$E$2:$E$2049,MATCH($D2049,title!$C$2:$C$2049,0),1),"") | J2049: =IF(AND(LENB(G2049),0<G2049,LENB(H2049),0<H2049),"●","") | K2049: =IF(LENB(J2049),COUNTIF(J$2:J2049,"●"),"") | L2049: =IF(AND(LENB(K2049),LENB($B$2),LENB($B$3)),$B$2+$B$3*(K2049),"") | M2049: =IF(LENB($L2049),$B$4&$L2049+COLUMN()-COLUMN($M2049)&".U = "&G2049&CHAR(9)&"'"&M$1,"") | O2049: =IF(LENB($L2049),$B$4&$L2049+COLUMN()-COLUMN($M2049)&".U = "&H2049&CHAR(9)&"'"&O$1,"") | P2049: =IF(LENB($L2049),$B$4&$L2049+COLUMN()-COLUMN($M2049)&".U = "&I2049&CHAR(9)&"'"&P$1,"") | Q2049: =IF(LENB(K2049),IF(1<K2049,CHAR(10),"")&"'"&IF(F2049=0,"名称未設定",F2049)&CHAR(10)&M2049&CHAR(10)&O2049&CHAR(10)&P2049,"")
K2051: 全ウィンドウ数
K2052: =MAX(K$2:K$2049) -> 36 | Q2052: =IF(LENB($B$6),"'"&$B$6,"")&CHAR(10)&_xlfn.CONCAT(Q$2:Q$2049)&CHAR(10)&CHAR(10)&"'合計ウィンドウ数"&CHAR(10)&$B$4&TEXT($B$2,"0000")&" = "&$K$2052&IF(LENB($B$7),CHAR(10)&"'"&$B$7,"") -> 'このスクリプトは C:\tk\prj\hg-0025-0016\git\kv-x520\doc\[kv_script_conv_TP1_popup.xlsx]title_scripts(変数) によって生成されました。 '軸1 タイトル DM8264.U = 1000 'ウィンドウNo. DM8266.U = 800 '幅 DM8267.U = 32 '高さ '軸2 タイトル DM8268.U = 1005 'ウィンドウNo. DM8270.U = 800 '幅 DM8271.U = 32 '高さ '軸3 タイトル DM8272.U = 1010 'ウィンドウNo. DM8274.U = 800 '幅 DM8275.U = 32 '高さ '軸4 タイトル DM8276.U = 1015 'ウィンドウNo. DM8278.U = 800 '幅 DM8279.U = 32 '高さ '軸5 タイトル DM8280.U = 1020 'ウィンドウNo. DM8282.U = 800 '幅 DM8283.U = 32 '高さ '軸6 タイトル DM8284.U = 1025 'ウィンドウNo. DM8286.U = 800 '幅 DM8287.U = 32 '高さ '軸7 タイトル DM8288.U = 1030 'ウィンドウNo. DM8290.U = 800 '幅 DM8291.U = 32 '高さ '軸8 タイトル DM8292.U = 1035 'ウィンドウNo. DM8294.U = 800 '幅 DM8295.U = 32 '高さ '軸9 タイトル DM8296.U = 1040 'ウィンドウNo. DM8298.U = 800 '幅 DM8299.U = 32 '高さ '軸10 タイトル DM8300.U = 1045 'ウィンドウNo. DM8302.U = 800 '幅 DM8303.U = 32 '高さ '軸11 タイトル DM8304.U = 1050 'ウィンドウNo. DM8306.U = 800 '幅 DM8307.U = 32 '高さ '軸12 タイトル DM8308.U = 1055 'ウィンドウNo. DM8310.U = 800 '幅 DM8311.U = 32 '高さ '軸13 タイトル DM8312.U = 1060 'ウィンドウNo. DM8314.U = 800 '幅 DM8315.U = 32 '高さ '軸14 タイトル DM8316.U = 1065 'ウィンドウNo. DM8318.U = 800 '幅 DM8319.U = 32 '高さ '軸15 タイトル DM8320.U = 1070 'ウィンドウNo. DM8322.U = 800 '幅 DM8323.U = 32 '高さ '軸16 タイトル DM8324.U = 1075 'ウィンドウNo. DM8326.U = 800 '幅 DM8327.U = 32 '高さ 'シリンダ1 タイトル DM8328.U = 1100 'ウィンドウNo. DM8330.U = 800 '幅 DM8331.U = 32 '高さ 'シリンダ2 タイトル DM8332.U = 1104 'ウィンドウNo. DM8334.U = 800 '幅 DM8335.U = 32 '高さ 'シリンダ3 タイトル DM8336.U = 1108 'ウィンドウNo. DM8338.U = 800 '幅 DM8339.U = 32 '高さ 'シリンダ4 タイトル DM8340.U = 1112 'ウィンドウNo. DM8342.U = 800 '幅 DM8343.U = 32 '高さ 'シリンダ5 タイトル DM8344.U = 1116 'ウィンドウNo. DM8346.U = 800 '幅 DM8347.U = 32 '高さ 'シリンダ6 タイトル DM8348.U = 1120 'ウィンドウNo. DM8350.U = 800 '幅 DM8351.U = 32 '高さ 'シリンダ7 タイトル DM8352.U = 1124 'ウィンドウNo. DM8354.U = 800 '幅 DM8355.U = 32 '高さ 'シリンダ8 タイトル DM8356.U = 1128 'ウィンドウNo. DM8358.U = 800 '幅 DM8359.U = 32 '高さ 'シリンダ9 タイトル DM8360.U = 1132 'ウィンドウNo. DM8362.U = 800 '幅 DM8363.U = 32 '高さ 'シリンダ10 タイトル DM8364.U = 1136 'ウィンドウNo. DM8366.U = 800 '幅 DM8367.U = 32 '高さ 'シリンダ11 タイトル DM8368.U = 1140 'ウィンドウNo. DM8370.U = 800 '幅 DM8371.U = 32 '高さ 'シリンダ12 タイトル DM8372.U = 1144 'ウィンドウNo. DM8374.U = 800 '幅 DM8375.U = 32 '高さ 'シリンダ13 タイトル DM8376.U = 1148 'ウィンドウNo. DM8378.U = 800 '幅 DM8379.U = 32 '高さ 'シリンダ14 タイトル DM8380.U = 1152 'ウィンドウNo. DM8382.U = 800 '幅 DM8383.U = 32 '高さ 'シリンダ15 タイトル DM8384.U = 1156 'ウィンドウNo. DM8386.U = 800 '幅 DM8387.U = 32 '高さ 'シリンダ16 タイトル DM8388.U = 1160 'ウィンドウNo. DM8390.U = 800 '幅 DM8391.U = 32 '高さ 'シリンダ17 タイトル DM8392.U = 1164 'ウィンドウNo. DM8394.U = 800 '幅 DM8395.U = 32 '高さ 'シリンダ18 タイトル DM8396.U = 1168 'ウィンドウNo. DM8398.U = 800 '幅 DM8399.U = 32 '高さ 'シリンダ19 タイトル DM8400.U = 1172 'ウィンドウNo. DM8402.U = 800 '幅 DM8403.U = 32 '高さ 'エレシリ1 タイトル DM8404.U = 1200 'ウィンドウNo. DM8406.U = 800 '幅 DM8407.U = 32 '高さ '合計ウィンドウ数 DM8260 = 36 '-----ここまで生成script-----

Sheet title_scripts(変数)
T1: 0 | U1: 1 | V1: 2
T2: =IFERROR(INDEX($B$35:$B$44,MATCH(T$1,$A$35:$A$44,0),1),"") -> No | U2: =IFERROR(INDEX($B$35:$B$44,MATCH(U$1,$A$35:$A$44,0),1),"") -> Wide | V2: =IFERROR(INDEX($B$35:$B$44,MATCH(V$1,$A$35:$A$44,0),1),"") -> Height
A3: 緒言 | E3: ウィンドウNo. | F3: id | G3: 名称 | H3: ウィンドウNo. | I3: 幅 | J3: 高さ | N3: ウィンドウあり | O3: ウィンドウ数 | P3: デバイス番号 | Q3: データあり | R3: カウント | S3: 変数 | T3: =IFERROR(INDEX($C$35:$C$44,MATCH(T$1,$A$35:$A$44,0),1),"") -> ｳｨﾝﾄﾞｳNo. | U3: =IFERROR(INDEX($C$35:$C$44,MATCH(U$1,$A$35:$A$44,0),1),"") -> ｳｨﾝﾄﾞｳ幅 | V3: =IFERROR(INDEX($C$35:$C$44,MATCH(V$1,$A$35:$A$44,0),1),"") -> ｳｨﾝﾄﾞｳ高さ | Z3: スクリプト
A4: 開始デバイス | B4: 8260 | E4: 0 | F4: =IFERROR(INDEX(title!$A$2:$A$2049,MATCH($E4,title!$C$2:$C$2049,0),1),"") | G4: =IFERROR(INDEX(title!$B$2:$B$2049,MATCH($E4,title!$C$2:$C$2049,0),1),"") | H4: =IFERROR(INDEX(title!$C$2:$C$2049,MATCH($E4,title!$C$2:$C$2049,0),1),"") | I4: =IFERROR(INDEX(title!$D$2:$D$2049,MATCH($E4,title!$C$2:$C$2049,0),1),"") | J4: =IFERROR(INDEX(title!$E$2:$E$2049,MATCH($E4,title!$C$2:$C$2049,0),1),"") | N4: =IF(AND(LENB(H4),0<H4,LENB(I4),0<I4),"●","") | O4: =IF(LENB(N4),COUNTIF(N$4:N4,"●"),"") | P4: =IF(AND(LENB(O4),LENB($B$4),LENB($B$5)),$B$4+$B$5*(O4),"") | Q4: =IF(LEN(G4),1,"") | R4: =IF(LEN(Q4),SUM($Q$4:Q4)-1,"") | S4: =IF(LENB($P4),IF(COUNTIF($B$34,"*[*"),REPLACE($B$34,FIND("[",$B$34),2,"["&$R4&"]"),$B$34),"") | T4: =IF(LENB($P4),$S4&"."&T$2&CHAR(9)&$B$8&" "&H4&$B$9&CHAR(9)&$B$7&T$3,"") | U4: =IF(LENB($P4),$S4&"."&U$2&CHAR(9)&$B$8&" "&I4&$B$9&CHAR(9)&$B$7&U$3,"") | V4: =IF(LENB($P4),$S4&"."&V$2&CHAR(9)&$B$8&" "&J4&$B$9&CHAR(9)&$B$7&V$3,"") | Z4: {=IF(LENB(O4:O2051),IF(1<O4:O2051,CHAR(10),"")&$B$7&IF(G4:G2051=0,"名称未設定",G4:G2051)&CHAR(10)&T4:T2051&CHAR(10)&U4:U2051&CHAR(10)&V4:V2051,"")}
A5: デバイス間隔 | B5: 4 | E5: 1 | F5: =IFERROR(INDEX(title!$A$2:$A$2049,MATCH($E5,title!$C$2:$C$2049,0),1),"") | G5: =IFERROR(INDEX(title!$B$2:$B$2049,MATCH($E5,title!$C$2:$C$2049,0),1),"") | H5: =IFERROR(INDEX(title!$C$2:$C$2049,MATCH($E5,title!$C$2:$C$2049,0),1),"") | I5: =IFERROR(INDEX(title!$D$2:$D$2049,MATCH($E5,title!$C$2:$C$2049,0),1),"") | J5: =IFERROR(INDEX(title!$E$2:$E$2049,MATCH($E5,title!$C$2:$C$2049,0),1),"") | N5: =IF(AND(LENB(H5),0<H5,LENB(I5),0<I5),"●","") | O5: =IF(LENB(N5),COUNTIF(N$4:N5,"●"),"") | P5: =IF(AND(LENB(O5),LENB($B$4),LENB($B$5)),$B$4+$B$5*(O5),"") | Q5: =IF(LEN(G5),1,"") | R5: =IF(LEN(Q5),SUM($Q$4:Q5)-1,"") | S5: =IF(LENB($P5),IF(COUNTIF($B$34,"*[*"),REPLACE($B$34,FIND("[",$B$34),2,"["&$R5&"]"),$B$34),"") | T5: =IF(LENB($P5),$S5&"."&T$2&CHAR(9)&$B$8&" "&H5&$B$9&CHAR(9)&$B$7&T$3,"") | U5: =IF(LENB($P5),$S5&"."&U$2&CHAR(9)&$B$8&" "&I5&$B$9&CHAR(9)&$B$7&U$3,"") | V5: =IF(LENB($P5),$S5&"."&V$2&CHAR(9)&$B$8&" "&J5&$B$9&CHAR(9)&$B$7&V$3,"")
A6: デバイス種別 | B6: DM | E6: 2 | F6: =IFERROR(INDEX(title!$A$2:$A$2049,MATCH($E6,title!$C$2:$C$2049,0),1),"") | G6: =IFERROR(INDEX(title!$B$2:$B$2049,MATCH($E6,title!$C$2:$C$2049,0),1),"") | H6: =IFERROR(INDEX(title!$C$2:$C$2049,MATCH($E6,title!$C$2:$C$2049,0),1),"") | I6: =IFERROR(INDEX(title!$D$2:$D$2049,MATCH($E6,title!$C$2:$C$2049,0),1),"") | J6: =IFERROR(INDEX(title!$E$2:$E$2049,MATCH($E6,title!$C$2:$C$2049,0),1),"") | N6: =IF(AND(LENB(H6),0<H6,LENB(I6),0<I6),"●","") | O6: =IF(LENB(N6),COUNTIF(N$4:N6,"●"),"") | P6: =IF(AND(LENB(O6),LENB($B$4),LENB($B$5)),$B$4+$B$5*(O6),"") | Q6: =IF(LEN(G6),1,"") | R6: =IF(LEN(Q6),SUM($Q$4:Q6)-1,"") | S6: =IF(LENB($P6),IF(COUNTIF($B$34,"*[*"),REPLACE($B$34,FIND("[",$B$34),2,"["&$R6&"]"),$B$34),"") | T6: =IF(LENB($P6),$S6&"."&T$2&CHAR(9)&$B$8&" "&H6&$B$9&CHAR(9)&$B$7&T$3,"") | U6: =IF(LENB($P6),$S6&"."&U$2&CHAR(9)&$B$8&" "&I6&$B$9&CHAR(9)&$B$7&U$3,"") | V6: =IF(LENB($P6),$S6&"."&V$2&CHAR(9)&$B$8&" "&J6&$B$9&CHAR(9)&$B$7&V$3,"")
A7: コメント表記 | B7: // | E7: 3 | F7: =IFERROR(INDEX(title!$A$2:$A$2049,MATCH($E7,title!$C$2:$C$2049,0),1),"") | G7: =IFERROR(INDEX(title!$B$2:$B$2049,MATCH($E7,title!$C$2:$C$2049,0),1),"") | H7: =IFERROR(INDEX(title!$C$2:$C$2049,MATCH($E7,title!$C$2:$C$2049,0),1),"") | I7: =IFERROR(INDEX(title!$D$2:$D$2049,MATCH($E7,title!$C$2:$C$2049,0),1),"") | J7: =IFERROR(INDEX(title!$E$2:$E$2049,MATCH($E7,title!$C$2:$C$2049,0),1),"") | N7: =IF(AND(LENB(H7),0<H7,LENB(I7),0<I7),"●","") | O7: =IF(LENB(N7),COUNTIF(N$4:N7,"●"),"") | P7: =IF(AND(LENB(O7),LENB($B$4),LENB($B$5)),$B$4+$B$5*(O7),"") | Q7: =IF(LEN(G7),1,"") | R7: =IF(LEN(Q7),SUM($Q$4:Q7)-1,"") | S7: =IF(LENB($P7),IF(COUNTIF($B$34,"*[*"),REPLACE($B$34,FIND("[",$B$34),2,"["&$R7&"]"),$B$34),"") | T7: =IF(LENB($P7),$S7&"."&T$2&CHAR(9)&$B$8&" "&H7&$B$9&CHAR(9)&$B$7&T$3,"") | U7: =IF(LENB($P7),$S7&"."&U$2&CHAR(9)&$B$8&" "&I7&$B$9&CHAR(9)&$B$7&U$3,"") | V7: =IF(LENB($P7),$S7&"."&V$2&CHAR(9)&$B$8&" "&J7&$B$9&CHAR(9)&$B$7&V$3,"")
A8: 代入式 | B8: := | E8: 4 | F8: =IFERROR(INDEX(title!$A$2:$A$2049,MATCH($E8,title!$C$2:$C$2049,0),1),"") | G8: =IFERROR(INDEX(title!$B$2:$B$2049,MATCH($E8,title!$C$2:$C$2049,0),1),"") | H8: =IFERROR(INDEX(title!$C$2:$C$2049,MATCH($E8,title!$C$2:$C$2049,0),1),"") | I8: =IFERROR(INDEX(title!$D$2:$D$2049,MATCH($E8,title!$C$2:$C$2049,0),1),"") | J8: =IFERROR(INDEX(title!$E$2:$E$2049,MATCH($E8,title!$C$2:$C$2049,0),1),"") | N8: =IF(AND(LENB(H8),0<H8,LENB(I8),0<I8),"●","") | O8: =IF(LENB(N8),COUNTIF(N$4:N8,"●"),"") | P8: =IF(AND(LENB(O8),LENB($B$4),LENB($B$5)),$B$4+$B$5*(O8),"") | Q8: =IF(LEN(G8),1,"") | R8: =IF(LEN(Q8),SUM($Q$4:Q8)-1,"") | S8: =IF(LENB($P8),IF(COUNTIF($B$34,"*[*"),REPLACE($B$34,FIND("[",$B$34),2,"["&$R8&"]"),$B$34),"") | T8: =IF(LENB($P8),$S8&"."&T$2&CHAR(9)&$B$8&" "&H8&$B$9&CHAR(9)&$B$7&T$3,"") | U8: =IF(LENB($P8),$S8&"."&U$2&CHAR(9)&$B$8&" "&I8&$B$9&CHAR(9)&$B$7&U$3,"") | V8: =IF(LENB($P8),$S8&"."&V$2&CHAR(9)&$B$8&" "&J8&$B$9&CHAR(9)&$B$7&V$3,"")
A9: 代入末尾 | B9: ; | E9: 5 | F9: =IFERROR(INDEX(title!$A$2:$A$2049,MATCH($E9,title!$C$2:$C$2049,0),1),"") | G9: =IFERROR(INDEX(title!$B$2:$B$2049,MATCH($E9,title!$C$2:$C$2049,0),1),"") | H9: =IFERROR(INDEX(title!$C$2:$C$2049,MATCH($E9,title!$C$2:$C$2049,0),1),"") | I9: =IFERROR(INDEX(title!$D$2:$D$2049,MATCH($E9,title!$C$2:$C$2049,0),1),"") | J9: =IFERROR(INDEX(title!$E$2:$E$2049,MATCH($E9,title!$C$2:$C$2049,0),1),"") | N9: =IF(AND(LENB(H9),0<H9,LENB(I9),0<I9),"●","") | O9: =IF(LENB(N9),COUNTIF(N$4:N9,"●"),"") | P9: =IF(AND(LENB(O9),LENB($B$4),LENB($B$5)),$B$4+$B$5*(O9),"") | Q9: =IF(LEN(G9),1,"") | R9: =IF(LEN(Q9),SUM($Q$4:Q9)-1,"") | S9: =IF(LENB($P9),IF(COUNTIF($B$34,"*[*"),REPLACE($B$34,FIND("[",$B$34),2,"["&$R9&"]"),$B$34),"") | T9: =IF(LENB($P9),$S9&"."&T$2&CHAR(9)&$B$8&" "&H9&$B$9&CHAR(9)&$B$7&T$3,"") | U9: =IF(LENB($P9),$S9&"."&U$2&CHAR(9)&$B$8&" "&I9&$B$9&CHAR(9)&$B$7&U$3,"") | V9: =IF(LENB($P9),$S9&"."&V$2&CHAR(9)&$B$8&" "&J9&$B$9&CHAR(9)&$B$7&V$3,"")
A10: 先頭注記 | B10: ="このスクリプトは "&B15&" によって生成されました。" -> このスクリプトは C:\tk\prj\hg-0025-0016\git\kv-x520\doc\[kv_script_conv_TP1_popup.xlsx]title_scripts(変数) によって生成されました。 | E10: 6 | F10: =IFERROR(INDEX(title!$A$2:$A$2049,MATCH($E10,title!$C$2:$C$2049,0),1),"") | G10: =IFERROR(INDEX(title!$B$2:$B$2049,MATCH($E10,title!$C$2:$C$2049,0),1),"") | H10: =IFERROR(INDEX(title!$C$2:$C$2049,MATCH($E10,title!$C$2:$C$2049,0),1),"") | I10: =IFERROR(INDEX(title!$D$2:$D$2049,MATCH($E10,title!$C$2:$C$2049,0),1),"") | J10: =IFERROR(INDEX(title!$E$2:$E$2049,MATCH($E10,title!$C$2:$C$2049,0),1),"") | N10: =IF(AND(LENB(H10),0<H10,LENB(I10),0<I10),"●","") | O10: =IF(LENB(N10),COUNTIF(N$4:N10,"●"),"") | P10: =IF(AND(LENB(O10),LENB($B$4),LENB($B$5)),$B$4+$B$5*(O10),"") | Q10: =IF(LEN(G10),1,"") | R10: =IF(LEN(Q10),SUM($Q$4:Q10)-1,"") | S10: =IF(LENB($P10),IF(COUNTIF($B$34,"*[*"),REPLACE($B$34,FIND("[",$B$34),2,"["&$R10&"]"),$B$34),"") | T10: =IF(LENB($P10),$S10&"."&T$2&CHAR(9)&$B$8&" "&H10&$B$9&CHAR(9)&$B$7&T$3,"") | U10: =IF(LENB($P10),$S10&"."&U$2&CHAR(9)&$B$8&" "&I10&$B$9&CHAR(9)&$B$7&U$3,"") | V10: =IF(LENB($P10),$S10&"."&V$2&CHAR(9)&$B$8&" "&J10&$B$9&CHAR(9)&$B$7&V$3,"")
A11: 末尾注記 | B11: -----ここまで生成script----- | E11: 7 | F11: =IFERROR(INDEX(title!$A$2:$A$2049,MATCH($E11,title!$C$2:$C$2049,0),1),"") | G11: =IFERROR(INDEX(title!$B$2:$B$2049,MATCH($E11,title!$C$2:$C$2049,0),1),"") | H11: =IFERROR(INDEX(title!$C$2:$C$2049,MATCH($E11,title!$C$2:$C$2049,0),1),"") | I11: =IFERROR(INDEX(title!$D$2:$D$2049,MATCH($E11,title!$C$2:$C$2049,0),1),"") | J11: =IFERROR(INDEX(title!$E$2:$E$2049,MATCH($E11,title!$C$2:$C$2049,0),1),"") | N11: =IF(AND(LENB(H11),0<H11,LENB(I11),0<I11),"●","") | O11: =IF(LENB(N11),COUNTIF(N$4:N11,"●"),"") | P11: =IF(AND(LENB(O11),LENB($B$4),LENB($B$5)),$B$4+$B$5*(O11),"") | Q11: =IF(LEN(G11),1,"") | R11: =IF(LEN(Q11),SUM($Q$4:Q11)-1,"") | S11: =IF(LENB($P11),IF(COUNTIF($B$34,"*[*"),REPLACE($B$34,FIND("[",$B$34),2,"["&$R11&"]"),$B$34),"") | T11: =IF(LENB($P11),$S11&"."&T$2&CHAR(9)&$B$8&" "&H11&$B$9&CHAR(9)&$B$7&T$3,"") | U11: =IF(LENB($P11),$S11&"."&U$2&CHAR(9)&$B$8&" "&I11&$B$9&CHAR(9)&$B$7&U$3,"") | V11: =IF(LENB($P11),$S11&"."&V$2&CHAR(9)&$B$8&" "&J11&$B$9&CHAR(9)&$B$7&V$3,"")
E12: 8 | F12: =IFERROR(INDEX(title!$A$2:$A$2049,MATCH($E12,title!$C$2:$C$2049,0),1),"") | G12: =IFERROR(INDEX(title!$B$2:$B$2049,MATCH($E12,title!$C$2:$C$2049,0),1),"") | H12: =IFERROR(INDEX(title!$C$2:$C$2049,MATCH($E12,title!$C$2:$C$2049,0),1),"") | I12: =IFERROR(INDEX(title!$D$2:$D$2049,MATCH($E12,title!$C$2:$C$2049,0),1),"") | J12: =IFERROR(INDEX(title!$E$2:$E$2049,MATCH($E12,title!$C$2:$C$2049,0),1),"") | N12: =IF(AND(LENB(H12),0<H12,LENB(I12),0<I12),"●","") | O12: =IF(LENB(N12),COUNTIF(N$4:N12,"●"),"") | P12: =IF(AND(LENB(O12),LENB($B$4),LENB($B$5)),$B$4+$B$5*(O12),"") | Q12: =IF(LEN(G12),1,"") | R12: =IF(LEN(Q12),SUM($Q$4:Q12)-1,"") | S12: =IF(LENB($P12),IF(COUNTIF($B$34,"*[*"),REPLACE($B$34,FIND("[",$B$34),2,"["&$R12&"]"),$B$34),"") | T12: =IF(LENB($P12),$S12&"."&T$2&CHAR(9)&$B$8&" "&H12&$B$9&CHAR(9)&$B$7&T$3,"") | U12: =IF(LENB($P12),$S12&"."&U$2&CHAR(9)&$B$8&" "&I12&$B$9&CHAR(9)&$B$7&U$3,"") | V12: =IF(LENB($P12),$S12&"."&V$2&CHAR(9)&$B$8&" "&J12&$B$9&CHAR(9)&$B$7&V$3,"")
E13: 9 | F13: =IFERROR(INDEX(title!$A$2:$A$2049,MATCH($E13,title!$C$2:$C$2049,0),1),"") | G13: =IFERROR(INDEX(title!$B$2:$B$2049,MATCH($E13,title!$C$2:$C$2049,0),1),"") | H13: =IFERROR(INDEX(title!$C$2:$C$2049,MATCH($E13,title!$C$2:$C$2049,0),1),"") | I13: =IFERROR(INDEX(title!$D$2:$D$2049,MATCH($E13,title!$C$2:$C$2049,0),1),"") | J13: =IFERROR(INDEX(title!$E$2:$E$2049,MATCH($E13,title!$C$2:$C$2049,0),1),"") | N13: =IF(AND(LENB(H13),0<H13,LENB(I13),0<I13),"●","") | O13: =IF(LENB(N13),COUNTIF(N$4:N13,"●"),"") | P13: =IF(AND(LENB(O13),LENB($B$4),LENB($B$5)),$B$4+$B$5*(O13),"") | Q13: =IF(LEN(G13),1,"") | R13: =IF(LEN(Q13),SUM($Q$4:Q13)-1,"") | S13: =IF(LENB($P13),IF(COUNTIF($B$34,"*[*"),REPLACE($B$34,FIND("[",$B$34),2,"["&$R13&"]"),$B$34),"") | T13: =IF(LENB($P13),$S13&"."&T$2&CHAR(9)&$B$8&" "&H13&$B$9&CHAR(9)&$B$7&T$3,"") | U13: =IF(LENB($P13),$S13&"."&U$2&CHAR(9)&$B$8&" "&I13&$B$9&CHAR(9)&$B$7&U$3,"") | V13: =IF(LENB($P13),$S13&"."&V$2&CHAR(9)&$B$8&" "&J13&$B$9&CHAR(9)&$B$7&V$3,"")
E14: 10 | F14: =IFERROR(INDEX(title!$A$2:$A$2049,MATCH($E14,title!$C$2:$C$2049,0),1),"") | G14: =IFERROR(INDEX(title!$B$2:$B$2049,MATCH($E14,title!$C$2:$C$2049,0),1),"") | H14: =IFERROR(INDEX(title!$C$2:$C$2049,MATCH($E14,title!$C$2:$C$2049,0),1),"") | I14: =IFERROR(INDEX(title!$D$2:$D$2049,MATCH($E14,title!$C$2:$C$2049,0),1),"") | J14: =IFERROR(INDEX(title!$E$2:$E$2049,MATCH($E14,title!$C$2:$C$2049,0),1),"") | N14: =IF(AND(LENB(H14),0<H14,LENB(I14),0<I14),"●","") | O14: =IF(LENB(N14),COUNTIF(N$4:N14,"●"),"") | P14: =IF(AND(LENB(O14),LENB($B$4),LENB($B$5)),$B$4+$B$5*(O14),"") | Q14: =IF(LEN(G14),1,"") | R14: =IF(LEN(Q14),SUM($Q$4:Q14)-1,"") | S14: =IF(LENB($P14),IF(COUNTIF($B$34,"*[*"),REPLACE($B$34,FIND("[",$B$34),2,"["&$R14&"]"),$B$34),"") | T14: =IF(LENB($P14),$S14&"."&T$2&CHAR(9)&$B$8&" "&H14&$B$9&CHAR(9)&$B$7&T$3,"") | U14: =IF(LENB($P14),$S14&"."&U$2&CHAR(9)&$B$8&" "&I14&$B$9&CHAR(9)&$B$7&U$3,"") | V14: =IF(LENB($P14),$S14&"."&V$2&CHAR(9)&$B$8&" "&J14&$B$9&CHAR(9)&$B$7&V$3,"")
A15: ファイル | B15: {=CELL("filename")} -> C:\tk\prj\hg-0025-0016\git\kv-x520\doc\[kv_script_conv_TP1_popup.xlsx]title_scripts(変数) | E15: 11 | F15: =IFERROR(INDEX(title!$A$2:$A$2049,MATCH($E15,title!$C$2:$C$2049,0),1),"") | G15: =IFERROR(INDEX(title!$B$2:$B$2049,MATCH($E15,title!$C$2:$C$2049,0),1),"") | H15: =IFERROR(INDEX(title!$C$2:$C$2049,MATCH($E15,title!$C$2:$C$2049,0),1),"") | I15: =IFERROR(INDEX(title!$D$2:$D$2049,MATCH($E15,title!$C$2:$C$2049,0),1),"") | J15: =IFERROR(INDEX(title!$E$2:$E$2049,MATCH($E15,title!$C$2:$C$2049,0),1),"") | N15: =IF(AND(LENB(H15),0<H15,LENB(I15),0<I15),"●","") | O15: =IF(LENB(N15),COUNTIF(N$4:N15,"●"),"") | P15: =IF(AND(LENB(O15),LENB($B$4),LENB($B$5)),$B$4+$B$5*(O15),"") | Q15: =IF(LEN(G15),1,"") | R15: =IF(LEN(Q15),SUM($Q$4:Q15)-1,"") | S15: =IF(LENB($P15),IF(COUNTIF($B$34,"*[*"),REPLACE($B$34,FIND("[",$B$34),2,"["&$R15&"]"),$B$34),"") | T15: =IF(LENB($P15),$S15&"."&T$2&CHAR(9)&$B$8&" "&H15&$B$9&CHAR(9)&$B$7&T$3,"") | U15: =IF(LENB($P15),$S15&"."&U$2&CHAR(9)&$B$8&" "&I15&$B$9&CHAR(9)&$B$7&U$3,"") | V15: =IF(LENB($P15),$S15&"."&V$2&CHAR(9)&$B$8&" "&J15&$B$9&CHAR(9)&$B$7&V$3,"")
E16: 12 | F16: =IFERROR(INDEX(title!$A$2:$A$2049,MATCH($E16,title!$C$2:$C$2049,0),1),"") | G16: =IFERROR(INDEX(title!$B$2:$B$2049,MATCH($E16,title!$C$2:$C$2049,0),1),"") | H16: =IFERROR(INDEX(title!$C$2:$C$2049,MATCH($E16,title!$C$2:$C$2049,0),1),"") | I16: =IFERROR(INDEX(title!$D$2:$D$2049,MATCH($E16,title!$C$2:$C$2049,0),1),"") | J16: =IFERROR(INDEX(title!$E$2:$E$2049,MATCH($E16,title!$C$2:$C$2049,0),1),"") | N16: =IF(AND(LENB(H16),0<H16,LENB(I16),0<I16),"●","") | O16: =IF(LENB(N16),COUNTIF(N$4:N16,"●"),"") | P16: =IF(AND(LENB(O16),LENB($B$4),LENB($B$5)),$B$4+$B$5*(O16),"") | Q16: =IF(LEN(G16),1,"") | R16: =IF(LEN(Q16),SUM($Q$4:Q16)-1,"") | S16: =IF(LENB($P16),IF(COUNTIF($B$34,"*[*"),REPLACE($B$34,FIND("[",$B$34),2,"["&$R16&"]"),$B$34),"") | T16: =IF(LENB($P16),$S16&"."&T$2&CHAR(9)&$B$8&" "&H16&$B$9&CHAR(9)&$B$7&T$3,"") | U16: =IF(LENB($P16),$S16&"."&U$2&CHAR(9)&$B$8&" "&I16&$B$9&CHAR(9)&$B$7&U$3,"") | V16: =IF(LENB($P16),$S16&"."&V$2&CHAR(9)&$B$8&" "&J16&$B$9&CHAR(9)&$B$7&V$3,"")
E17: 13 | F17: =IFERROR(INDEX(title!$A$2:$A$2049,MATCH($E17,title!$C$2:$C$2049,0),1),"") | G17: =IFERROR(INDEX(title!$B$2:$B$2049,MATCH($E17,title!$C$2:$C$2049,0),1),"") | H17: =IFERROR(INDEX(title!$C$2:$C$2049,MATCH($E17,title!$C$2:$C$2049,0),1),"") | I17: =IFERROR(INDEX(title!$D$2:$D$2049,MATCH($E17,title!$C$2:$C$2049,0),1),"") | J17: =IFERROR(INDEX(title!$E$2:$E$2049,MATCH($E17,title!$C$2:$C$2049,0),1),"") | N17: =IF(AND(LENB(H17),0<H17,LENB(I17),0<I17),"●","") | O17: =IF(LENB(N17),COUNTIF(N$4:N17,"●"),"") | P17: =IF(AND(LENB(O17),LENB($B$4),LENB($B$5)),$B$4+$B$5*(O17),"") | Q17: =IF(LEN(G17),1,"") | R17: =IF(LEN(Q17),SUM($Q$4:Q17)-1,"") | S17: =IF(LENB($P17),IF(COUNTIF($B$34,"*[*"),REPLACE($B$34,FIND("[",$B$34),2,"["&$R17&"]"),$B$34),"") | T17: =IF(LENB($P17),$S17&"."&T$2&CHAR(9)&$B$8&" "&H17&$B$9&CHAR(9)&$B$7&T$3,"") | U17: =IF(LENB($P17),$S17&"."&U$2&CHAR(9)&$B$8&" "&I17&$B$9&CHAR(9)&$B$7&U$3,"") | V17: =IF(LENB($P17),$S17&"."&V$2&CHAR(9)&$B$8&" "&J17&$B$9&CHAR(9)&$B$7&V$3,"")
E18: 14 | F18: =IFERROR(INDEX(title!$A$2:$A$2049,MATCH($E18,title!$C$2:$C$2049,0),1),"") | G18: =IFERROR(INDEX(title!$B$2:$B$2049,MATCH($E18,title!$C$2:$C$2049,0),1),"") | H18: =IFERROR(INDEX(title!$C$2:$C$2049,MATCH($E18,title!$C$2:$C$2049,0),1),"") | I18: =IFERROR(INDEX(title!$D$2:$D$2049,MATCH($E18,title!$C$2:$C$2049,0),1),"") | J18: =IFERROR(INDEX(title!$E$2:$E$2049,MATCH($E18,title!$C$2:$C$2049,0),1),"") | N18: =IF(AND(LENB(H18),0<H18,LENB(I18),0<I18),"●","") | O18: =IF(LENB(N18),COUNTIF(N$4:N18,"●"),"") | P18: =IF(AND(LENB(O18),LENB($B$4),LENB($B$5)),$B$4+$B$5*(O18),"") | Q18: =IF(LEN(G18),1,"") | R18: =IF(LEN(Q18),SUM($Q$4:Q18)-1,"") | S18: =IF(LENB($P18),IF(COUNTIF($B$34,"*[*"),REPLACE($B$34,FIND("[",$B$34),2,"["&$R18&"]"),$B$34),"") | T18: =IF(LENB($P18),$S18&"."&T$2&CHAR(9)&$B$8&" "&H18&$B$9&CHAR(9)&$B$7&T$3,"") | U18: =IF(LENB($P18),$S18&"."&U$2&CHAR(9)&$B$8&" "&I18&$B$9&CHAR(9)&$B$7&U$3,"") | V18: =IF(LENB($P18),$S18&"."&V$2&CHAR(9)&$B$8&" "&J18&$B$9&CHAR(9)&$B$7&V$3,"")
E19: 15 | F19: =IFERROR(INDEX(title!$A$2:$A$2049,MATCH($E19,title!$C$2:$C$2049,0),1),"") | G19: =IFERROR(INDEX(title!$B$2:$B$2049,MATCH($E19,title!$C$2:$C$2049,0),1),"") | H19: =IFERROR(INDEX(title!$C$2:$C$2049,MATCH($E19,title!$C$2:$C$2049,0),1),"") | I19: =IFERROR(INDEX(title!$D$2:$D$2049,MATCH($E19,title!$C$2:$C$2049,0),1),"") | J19: =IFERROR(INDEX(title!$E$2:$E$2049,MATCH($E19,title!$C$2:$C$2049,0),1),"") | N19: =IF(AND(LENB(H19),0<H19,LENB(I19),0<I19),"●","") | O19: =IF(LENB(N19),COUNTIF(N$4:N19,"●"),"") | P19: =IF(AND(LENB(O19),LENB($B$4),LENB($B$5)),$B$4+$B$5*(O19),"") | Q19: =IF(LEN(G19),1,"") | R19: =IF(LEN(Q19),SUM($Q$4:Q19)-1,"") | S19: =IF(LENB($P19),IF(COUNTIF($B$34,"*[*"),REPLACE($B$34,FIND("[",$B$34),2,"["&$R19&"]"),$B$34),"") | T19: =IF(LENB($P19),$S19&"."&T$2&CHAR(9)&$B$8&" "&H19&$B$9&CHAR(9)&$B$7&T$3,"") | U19: =IF(LENB($P19),$S19&"."&U$2&CHAR(9)&$B$8&" "&I19&$B$9&CHAR(9)&$B$7&U$3,"") | V19: =IF(LENB($P19),$S19&"."&V$2&CHAR(9)&$B$8&" "&J19&$B$9&CHAR(9)&$B$7&V$3,"")
